Workbook
Name Date: Regist!$H$1
Name Fleet_Dest: Fleet_Det!$G$7
Name Input_Fleet_Dest: INDEX(_xlfn.ANCHORARRAY(Fleet_Det!$AB$4), ROW(Front_Des[[#This Row],[Dest]])-ROW(Front_Des[#Headers]),)
Name Input_Fleet_Identic: INDEX(_xlfn.ANCHORARRAY(Fleet_Det!$BL$4),ROW(Front_Des[[#This Row],[Fleet Reff]])-ROW(Front_Des[#Headers]),)
Name Input_Fleet_Truck: INDEX(_xlfn.ANCHORARRAY(Fleet_Det!$CE$4),ROW(Front_Des[[#This Row],[Dest]])-ROW(Front_Des[#Headers]),)
Name Input_Pile: INDEX(_xlfn.ANCHORARRAY(Regist!$AO$8),ROW(Sample_Pending[[#This Row],[Pile_ID]])-ROW(Sample_Pending[#Headers]),)
Name Input_Truck: INDEX(_xlfn.ANCHORARRAY(Pile_01!$AP$5),ROW(HLG_01[[#This Row],[Truck_ID]])-ROW(HLG_01[#Headers]),)
Name Input_Truck: INDEX(_xlfn.ANCHORARRAY(Pile_02!$AP$5),ROW(HLG_02[[#This Row],[Truck_ID]])-ROW(HLG_02[#Headers]),)
Name Input_Truck: INDEX(_xlfn.ANCHORARRAY(Pile_03!$AP$5),ROW(HLG_03[[#This Row],[Truck_ID]])-ROW(HLG_03[#Headers]),)
Name Input_Truck: INDEX(_xlfn.ANCHORARRAY(Pile_04!$AP$5),ROW(HLG_04[[#This Row],[Truck_ID]])-ROW(HLG_04[#Headers]),)
Name Input_Truck: INDEX(_xlfn.ANCHORARRAY(Pile_05!$AP$5),ROW(HLG_05[[#This Row],[Truck_ID]])-ROW(HLG_05[#Headers]),)
Name Input_Truck: INDEX(_xlfn.ANCHORARRAY(Pile_06!$AP$5),ROW(HLG_06[[#This Row],[Truck_ID]])-ROW(HLG_06[#Headers]),)
Name List_Front: _xlfn.ANCHORARRAY(Fleet_Det!$A$4)
Name List_Unit_Fleet: _xlfn.ANCHORARRAY(Fleet_Det!$AA$4)
Name Pilih_Truck: IFERROR(GET_TRUCK(INDEX(HLG_01[Front_ID], ROW() - ROW(HLG_01[#Headers]))), "" )
Name Report_Header: _xlfn.ANCHORARRAY(Regist!$AH$1)
Name Shift: Regist!$I$1
Name Smpl_Pos_IncrFrom: INDEX(_xlfn.ANCHORARRAY(Sample_Pos!$BZ$3),ROW(Sample_Pos[[#This Row],[Batch]])-ROW(Sample_Pos[#Headers]),)
Name Truck_ID: _xlfn.ANCHORARRAY(Truck!$A$2)

Sheet Rules
B1: NIK | C1: Name | E1: NIK | F1: EMP_NAME | G1: Job | I1: Sector | K1: Sector | L1: Sampling House | N1: sector | O1: stockpile | P1: pile_id | Q1: Ore | S1: Ore | U1: Ore | V1: Class | X1: Ore | Y1: Inc | Z1: Batch | AA1: Packing | AC1: Prep Stat
B2: SCM0268 | C2: Mega Putri Arisanda | E2: 220126 | F2: Apriyadi | I2: BR1 | K2: BR1 | L2: SH_01 | N2: BR1 | O2: BR-C_02 | P2: BR-C2_S05 | Q2: SAP | S2: {=_xlfn.LET(_xlpm.c, ISNUMBER(SEARCH("C",Pile_area[stockpile])), _xlpm.ls, ISNUMBER(SEARCH("LS",Pile_area[stockpile])), _xlpm.ss, ISNUMBER(SEARCH("SS",Pile_area[stockpile])), _xlpm.sap, ISNUMBER(SEARCH("S",Pile_area[pile_id])), _xlpm.lim, ISNUMBER(SEARCH("L",Pile_area[pile_id])), _xlpm.rslt, IF(Pile_area[pile_id]="","",IF((_xlpm.c*_xlpm.sap)+(_xlpm.ss*--(_xlpm.lim=FALSE)),"SAP","LIM")), _xlpm.lim=FALSE)} -> TRUE | U2: LIM | V2: LGLO | X2: SAP | Y2: 2 | Z2: 20 | AA2: 2 | AC2: BR1 | AG2: BR1_C02 | AH2: BR1-C2_S01
B3: SCM0285 | C3: Ajumarlan | E3: 220144 | F3: Rizal R | I3: DS | K3: BR1 | L3: SHT/C01 | N3: BR1 | O3: BR-C_02 | P3: BR-C2_S06 | Q3: SAP | S3: TRUE | U3: LIM | V3: MGLO | X3: LIM | Y3: 5 | Z3: 100 | AA3: 10 | AC3: DS | AH3: BR1C2_S01
B4: SCM0299 | C4: Imam Noor Setiadi | E4: 220194 | F4: Muhammad Farhan Zaini | I4: BR23W | K4: DS | L4: SH_01 | N4: BR1 | O4: BR-C_02 | P4: BR-C2_S07 | Q4: SAP | S4: TRUE | U4: LIM | V4: HGLO | AC4: BR23W
B5: SCM0333 | C5: Raharjo Rahman | E5: 220220 | F5: Yahazkiel Eka Putra | G5: Dispatcher | I5: BR23E | K5: DS | L5: SHT/C01 | N5: BR1 | O5: BR-C_02 | P5: BR-C2_S08 | Q5: SAP | S5: TRUE | U5: SAP | V5: LGSO(-)
B6: SCM0607 | C6: Imam Septian | E6: 220221 | F6: Muh. Rahmad Hidayat | I6: Eppe | K6: DS | L6: SHT/C05 | N6: BR1 | O6: BR-C_03 | P6: BR-C3_L08 | Q6: LIM | S6: FALSE | U6: SAP | V6: MWS
B7: SCM1040 | C7: Febi Prabowo | E7: 220229 | F7: Hasyim Asy'ari, S.Pd | I7: Jl_KNW | K7: DS | L7: SHT/SOM | N7: BR1 | O7: BR-C_03 | P7: BR-C3_L09 | Q7: LIM | S7: FALSE | U7: SAP | V7: LGSO
B8: SCM1135 | C8: Yusran Abu'bakar | E8: 230232 | F8: Saprianto | I8: Jl_SRG | K8: BR23E | L8: SHT/Road-AA | N8: BR1 | O8: BR-C_03 | P8: BR-C3_S05 | Q8: SAP | S8: TRUE | U8: SAP | V8: MGSO
B9: SCM1148 | C9: Sutomo Eka Putra | E9: 230235 | F9: Ismail | K9: BR23W | L9: SHT/Road-A | N9: BR1 | O9: BR-C_03 | P9: BR-C3B_S14 | Q9: SAP | S9: TRUE | U9: SAP | V9: HGSO
B10: SCM0290 | C10: Hardin | E10: 230240 | F10: Riswan Yamin | K10: BR23W | L10: SHT/Road-E | N10: BR1 | O10: BR-C_04 | P10: BR-C4_S06 | Q10: SAP | S10: TRUE
B11: SCM0293 | C11: Aswar Meilsandy | E11: 230255 | F11: Kurniawan M | N11: BR1 | O11: BR-C_06 | P11: BR-C6_L22 | Q11: LIM | S11: FALSE
B12: SCM0601 | C12: Erick Riyanto | E12: 230257 | F12: Rella Irawan | N12: BR1 | O12: BR-C_06 | P12: BR-C6_L23 | Q12: LIM | S12: FALSE
B13: SCM0606 | C13: Muh. Reski | E13: 230266 | F13: Yusran | N13: BR1 | O13: BR-C_06 | P13: BR-C6_S07 | Q13: SAP | S13: TRUE
B14: SCM0627 | C14: Wahyudin Madilao | E14: 230268 | F14: Takdir | N14: BR1 | O14: BR-C_06 | P14: BR-C6_S08 | Q14: SAP | S14: TRUE
B15: SCM0897 | C15: Aris Ashari | E15: 230278 | F15: Muh. Aditya Ariel Saputra | N15: BR1 | O15: BR-C_06 | P15: BR-C6C_S06 | Q15: SAP | S15: TRUE
B16: SCM0898 | C16: Yogi Ardianto | E16: 230314 | F16: Farmandaris Sattu Ponglanda | N16: BR1 | O16: BR-C_06 | P16: BR-C6C_S07 | Q16: SAP | S16: TRUE
B17: SCM0899 | C17: Rikal Ma'ruf | E17: 230322 | F17: Amrullah | N17: BR1 | O17: BR-C_06 | P17: BR-C6D_S06 | Q17: SAP | S17: TRUE
B18: SCM0931 | C18: Irwan | E18: 230323 | F18: Gustanto | N18: BR1 | O18: BR-C_06 | P18: BR-C6D_S16 | Q18: SAP | S18: TRUE
B19: SCM0932 | C19: Algiyul Belo Patiung | E19: 230324 | F19: Roni Hakim | N19: BR1 | O19: BR-C_12 | P19: BR-C12_L10 | Q19: LIM | S19: FALSE
B20: SCM1077 | C20: Krismala Ghiovanny Sepriyanti | E20: 230325 | F20: Herman Avandi Azis | N20: BR1 | O20: BR-C_12 | P20: BR-C12_L11 | Q20: LIM | S20: FALSE
B21: SCM1086 | C21: Muhammad Farhan Putra | E21: 230330 | F21: Ulhabri Hl Hasbuan | N21: BR1 | O21: C_02 | P21: BR-C2_S01 | Q21: SAP | S21: TRUE
B22: SCM1087 | C22: Ahmad Syaiful | E22: 230350 | F22: Ardi Abriansyah | N22: BR1 | O22: C_02 | P22: BR-C2_S02 | Q22: SAP | S22: TRUE
... B29: SCM1120 | C29: Teddy T W | E29: 240632 | F29: Alan Saputra | N29: BR1 | O29: C_03 | P29: C3_L03 | Q29: LIM | S29: FALSE
E30: 240641 | F30: Randy Safutra S | N30: BR1 | O30: C_03 | P30: C3_L04 | Q30: LIM | S30: FALSE
E31: 240642 | F31: La Ode Amir | N31: BR1 | O31: C_03 | P31: C3_L05 | Q31: LIM | S31: FALSE
E32: 240643 | F32: Adit Saputra | N32: BR1 | O32: C_03 | P32: C3_L06 | Q32: LIM | S32: FALSE
E33: 240644 | F33: Nabil_2 | N33: BR1 | O33: C_03 | P33: C3_L07 | Q33: LIM | S33: FALSE
E34: 240704 | F34: Deri | N34: BR1 | O34: C_03 | P34: C3_S01 | Q34: SAP | S34: TRUE
E35: 240817 | F35: Muhammad Syahrul | N35: BR1 | O35: C_03 | P35: C3_S02 | Q35: SAP | S35: TRUE
E36: 240818 | F36: Firman Salahuddin | G36: Dispatcher | N36: BR1 | O36: C_03 | P36: C3A_01 | Q36: SAP | S36: TRUE
E37: 240911 | F37: Rendy Perdana Putra | N37: BR1 | O37: C_03 | P37: C3A_02 | Q37: SAP | S37: TRUE
E38: 240914 | F38: Indra Febriansyah | N38: BR1 | O38: C_03 | P38: C3A_L04 | Q38: LIM | S38: FALSE
E39: 240915 | F39: Adryan Muhta Syam | G39: Dispatcher | N39: BR1 | O39: C_03 | P39: C3A_S03 | Q39: SAP | S39: TRUE
E40: 241001 | F40: Riki Ibranto | N40: BR1 | O40: C_03 | P40: C3A_S04 | Q40: SAP | S40: TRUE
E41: 241002 | F41: Adin | N41: BR1 | O41: C_03 | P41: C3B_02 | Q41: SAP | S41: TRUE
E42: 241015 | F42: Karunia Rener Simon Tandidatu | G42: Dispatcher | N42: BR1 | O42: C_03 | P42: C3B_03 | Q42: SAP | S42: TRUE
E43: 250403 | F43: Iqbal Ramdani | N43: BR1 | O43: C_03 | P43: C3B_04 | Q43: SAP | S43: TRUE
E44: 250405 | F44: Ferri Nur | N44: BR1 | O44: C_03 | P44: C3B_05 | Q44: SAP | S44: TRUE
E45: 250406 | F45: Hendrianto | N45: BR1 | O45: C_03 | P45: C3B_L05 | Q45: LIM | S45: FALSE
E46: 250413 | F46: Ash Habul Yamin | N46: BR1 | O46: C_03 | P46: C3B_L06 | Q46: LIM | S46: FALSE
...

Sheet Truck
A1: Truck_ID | B1: Input_Truck | C1: PF Type | F1: PT | G1: Model | H1: No | J1: Name of Hauler Owner | K1: Code | M1: Hauler Type | N1: Type | O1: PF | P1: Model | Q1: Code
A2: {=d_trucks[PT]&"-"&_xlfn.ANCHORARRAY($C$2)&"_"&TEXT(d_trucks[No],"0000")} -> RL-A40_0012 | B2: {=d_trucks[No]&"_"&d_trucks[Model]} -> 12_ADT40 | C2: {=_xlfn.XLOOKUP(d_trucks[Model],Table8[Model],Table8[Code],"")} -> A40 | D2: {=_xlfn.LET( _xlpm.arr, d_trucks[], _xlpm.blnk, _xlfn.BYROW(_xlpm.arr, _xlfn.LAMBDA(_xlpm.x, COUNTBLANK(_xlpm.x))), _xlpm.id, _xlfn.BYROW(_xlpm.arr, _xlfn.LAMBDA(_xlpm.r, _xlfn.CONCAT(_xlpm.r))), _xlpm.cnt, _xlfn.MAP(_xlpm.id, _xlfn.LAMBDA(_xlpm.x, SUM(--(_xlpm.id=_xlpm.x)*(_xlpm.id<>"")))), _xlpm.rslt,IF(_xlpm.blnk=COLUMNS(_xlpm.arr),_xlpm.cnt>1,_xlpm.blnk>0), _xlpm.rslt)} -> FALSE | F2: RL | G2: ADT40 | H2: 12 | J2: PT Hillconjaya Sukses | K2: HS | M2: Articulated Dump Truck | N2: ADT | O2: 40 | P2: =Table8[[#This Row],[Type]]&Table8[[#This Row],[PF]] -> ADT40 | Q2: {=_xlfn.LET( _xlpm.typ, Table8[[#This Row],[Type]], _xlpm.trck, IF(_xlpm.typ="TOT", _xlpm.typ, _xlfn.SWITCH(_xlpm.typ, "DT", "T", "ADT", "A")&Table8[[#This Row],[PF]]), IF(Table8[[#This Row],[Type]]="","",_xlpm.trck))} -> A40
A3: RL-A40_0013 | B3: 13_ADT40 | C3: A40 | D3: FALSE | F3: RL | G3: ADT40 | H3: 13 | J3: PT Sinar Terang Mandiri | K3: STM | M3: Dump Truck | N3: DT | O3: 20 | P3: =Table8[[#This Row],[Type]]&Table8[[#This Row],[PF]] -> DT20 | Q3: {=_xlfn.LET( _xlpm.typ, Table8[[#This Row],[Type]], _xlpm.trck, IF(_xlpm.typ="TOT", _xlpm.typ, _xlfn.SWITCH(_xlpm.typ, "DT", "T", "ADT", "A")&Table8[[#This Row],[PF]]), IF(Table8[[#This Row],[Type]]="","",_xlpm.trck))} -> T20
A4: RL-A40_0014 | B4: 14_ADT40 | C4: A40 | D4: FALSE | F4: RL | G4: ADT40 | H4: 14 | J4: PT Sinar Mulia Abadi | K4: SMA | M4: Dump Truck | N4: DT | O4: 30 | P4: =Table8[[#This Row],[Type]]&Table8[[#This Row],[PF]] -> DT30 | Q4: {=_xlfn.LET( _xlpm.typ, Table8[[#This Row],[Type]], _xlpm.trck, IF(_xlpm.typ="TOT", _xlpm.typ, _xlfn.SWITCH(_xlpm.typ, "DT", "T", "ADT", "A")&Table8[[#This Row],[PF]]), IF(Table8[[#This Row],[Type]]="","",_xlpm.trck))} -> T30
A5: RL-A40_0015 | B5: 15_ADT40 | C5: A40 | D5: FALSE | F5: RL | G5: ADT40 | H5: 15 | J5: PT Rajawali Emas Ancora Lestari | K5: RL | M5: Dump Truck | N5: DT | O5: 40 | P5: =Table8[[#This Row],[Type]]&Table8[[#This Row],[PF]] -> DT40 | Q5: {=_xlfn.LET( _xlpm.typ, Table8[[#This Row],[Type]], _xlpm.trck, IF(_xlpm.typ="TOT", _xlpm.typ, _xlfn.SWITCH(_xlpm.typ, "DT", "T", "ADT", "A")&Table8[[#This Row],[PF]]), IF(Table8[[#This Row],[Type]]="","",_xlpm.trck))} -> T40
A6: RL-A40_0016 | B6: 16_ADT40 | C6: A40 | D6: FALSE | F6: RL | G6: ADT40 | H6: 16 | J6: PT Putra Morowali Sejahtera | K6: PMS | P6: =Table8[[#This Row],[Type]]&Table8[[#This Row],[PF]] | Q6: {=_xlfn.LET( _xlpm.typ, Table8[[#This Row],[Type]], _xlpm.trck, IF(_xlpm.typ="TOT", _xlpm.typ, _xlfn.SWITCH(_xlpm.typ, "DT", "T", "ADT", "A")&Table8[[#This Row],[PF]]), IF(Table8[[#This Row],[Type]]="","",_xlpm.trck))}
A7: RL-A40_0017 | B7: 17_ADT40 | C7: A40 | D7: FALSE | F7: RL | G7: ADT40 | H7: 17 | J7: PT Mulia Rentalindo Persada | K7: MRP | P7: =Table8[[#This Row],[Type]]&Table8[[#This Row],[PF]] | Q7: {=_xlfn.LET( _xlpm.typ, Table8[[#This Row],[Type]], _xlpm.trck, IF(_xlpm.typ="TOT", _xlpm.typ, _xlfn.SWITCH(_xlpm.typ, "DT", "T", "ADT", "A")&Table8[[#This Row],[PF]]), IF(Table8[[#This Row],[Type]]="","",_xlpm.trck))}
A8: RL-A40_0018 | B8: 18_ADT40 | C8: A40 | D8: FALSE | F8: RL | G8: ADT40 | H8: 18 | J8: PT Teknologi Infrastruktur Indonesia | K8: TII | P8: =Table8[[#This Row],[Type]]&Table8[[#This Row],[PF]] | Q8: {=_xlfn.LET( _xlpm.typ, Table8[[#This Row],[Type]], _xlpm.trck, IF(_xlpm.typ="TOT", _xlpm.typ, _xlfn.SWITCH(_xlpm.typ, "DT", "T", "ADT", "A")&Table8[[#This Row],[PF]]), IF(Table8[[#This Row],[Type]]="","",_xlpm.trck))}
A9: RL-A40_0019 | B9: 19_ADT40 | C9: A40 | D9: FALSE | F9: RL | G9: ADT40 | H9: 19 | J9: PT Malachite International Mining | K9: MIM
A10: RL-A40_0020 | B10: 20_ADT40 | C10: A40 | D10: FALSE | F10: RL | G10: ADT40 | H10: 20
A11: RL-A40_0021 | B11: 21_ADT40 | C11: A40 | D11: FALSE | F11: RL | G11: ADT40 | H11: 21
A12: RL-A40_0022 | B12: 22_ADT40 | C12: A40 | D12: FALSE | F12: RL | G12: ADT40 | H12: 22
A13: RL-A40_0023 | B13: 23_ADT40 | C13: A40 | D13: FALSE | F13: RL | G13: ADT40 | H13: 23
A14: RL-A40_0024 | B14: 24_ADT40 | C14: A40 | D14: FALSE | F14: RL | G14: ADT40 | H14: 24
A15: RL-A40_0025 | B15: 25_ADT40 | C15: A40 | D15: FALSE | F15: RL | G15: ADT40 | H15: 25
A16: RL-A40_0026 | B16: 26_ADT40 | C16: A40 | D16: FALSE | F16: RL | G16: ADT40 | H16: 26
A17: RL-A40_0027 | B17: 27_ADT40 | C17: A40 | D17: FALSE | F17: RL | G17: ADT40 | H17: 27
A18: RL-A40_0029 | B18: 29_ADT40 | C18: A40 | D18: FALSE | F18: RL | G18: ADT40 | H18: 29
A19: RL-A40_0030 | B19: 30_ADT40 | C19: A40 | D19: FALSE | F19: RL | G19: ADT40 | H19: 30
A20: RL-A40_0031 | B20: 31_ADT40 | C20: A40 | D20: FALSE | F20: RL | G20: ADT40 | H20: 31
A21: RL-A40_0032 | B21: 32_ADT40 | C21: A40 | D21: FALSE | F21: RL | G21: ADT40 | H21: 32
... A151: STM-A40_2008 | B151: 2008_ADT40 | C151: A40 | D151: FALSE | F151: STM | G151: ADT40 | H151: 2008
A152: -_0000 | B152: _ | D152: FALSE
A153: -_0000 | B153: _ | D153: FALSE
A154: -_0000 | B154: _ | D154: FALSE
A155: -_0000 | B155: _ | D155: FALSE
A156: -_0000 | B156: _ | D156: FALSE
A157: -_0000 | B157: _ | D157: FALSE
A158: -_0000 | B158: _ | D158: FALSE
A159: -_0000 | B159: _ | D159: FALSE
A160: -_0000 | B160: _ | D160: FALSE
A161: -_0000 | B161: _ | D161: FALSE
A162: -_0000 | B162: _ | D162: FALSE
A163: -_0000 | B163: _ | D163: FALSE
... A384: -_0000 | B384: _ | D384: FALSE

Sheet Regist
B1: {=_xlfn.SEQUENCE(2,,TODAY(),-1)} -> 46249 | C1: {=_xlfn._xlws.FILTER(Location[Sampling House],Location[Sector]=$H$3)} -> SH_01 | D1: {=_xlfn.UNIQUE(_xlfn._xlws.FILTER(Pile_area[stockpile],(Pile_area[sector]=Regist!$H$3)))} -> BR-C_02 | G1: Date / Shift: | H1: 46211 | I1: D | AC1: * | AH1: {=_xlfn.LET( _xlpm.dy, "_Date/Shift: " & TEXT(Date, "dd-mmm-yy") &" / "& Shift &"_", _xlpm.week, "_Week: " & _xlfn.ISOWEEKNUM(Date) &"_", _xlpm.emp, _xlfn.HSTACK(_xlfn.VSTACK(IF(Person[NIK]>0, ""),Person4[Job]), _xlfn.VSTACK(Person[NIK],Person4[NIK]), _xlfn.VSTACK(_xlfn.ANCHORARRAY($H$8),_xlfn.ANCHORARRAY($I$19))), _xlpm.pic, _xlfn._xlws.FILTER(_xlpm.emp, _xlfn.DROP(_xlpm.emp,,2)<>""), _xlpm.dt, _xlfn.HSTACK(Date,Shift,$H$3&"/"&$H$5), _xlpm.pic_t, {"_*Date","Shift","Location","Job Desk","NIK","Name*_"}, _xlpm.pic_v, _xlfn.HSTACK(IF(_xlfn.DROP(_xlpm.pic,,2)>0, _xlpm.dt,""), _xlpm.pic), _xlpm.ttl, _xlfn.IFNA(_xlfn.VSTACK(_xlfn.VSTACK({"_Dear All,_";"*DAILY ORE QUALITY ASSURANCE REPORT*"},"_*-- Ore & Sample Production --*_",_xlpm.dy, _xlpm.week),"","*MANPOWER:*",_xlpm.pic_t,_xlpm.pic_v,""),""), _xlpm.ttl)} -> _Dear All,_ | DC1: * | EO1: *
B2: 46248 | C2: SHT/C01 | D2: BR-C_03 | AH2: *DAILY ORE QUALITY ASSURANCE REPORT*
D3: BR-C_04 | G3: Sector: | H3: BR1 | AH3: _*-- Ore & Sample Production --*_
D4: BR-C_06 | AH4: _Date/Shift: 08-Jul-26 / D_
D5: BR-C_12 | G5: Sampling: | H5: SH_01 | M5: PENDING SAMPLES | AH5: _Week: 28_
D6: C_02
D7: C_03 | G7: NIK | H7: Name | M7: Stockpile | N7: Pile_ID | O7: Batch | P7: Rit | Q7: Status | AH7: *MANPOWER:*
D8: C_04 | G8: SCM0333 | H8: {=IF(Person[NIK]="","",_xlfn.XLOOKUP(Person[NIK],Emply_Staff[NIK],Emply_Staff[Name]))} -> Raharjo Rahman | M8: SS_05 | N8: S5_88 | O8: 53 | P8: 8 | Q8: Cont | AD8: {=IF(Sample_Pending[Pile_ID]="","",_xlfn.XLOOKUP(Sample_Pending[Pile_ID],Pile_area[pile_id],Pile_area[Ore]))} -> SAP | AE8: {=IF(Front_Des[Front No]>0,Front_Des[Sector]&"/"&TEXT(Front_Des[Front No],"00"),"")} -> BR1/01 | AF8: {=IF(_xlfn.ANCHORARRAY($AE$8)="","",COUNTIF(_xlfn.ANCHORARRAY($AE$8),_xlfn.ANCHORARRAY($AE$8)))} -> 1 | AH8: _*Date | AI8: Shift | AJ8: Location | AK8: Job Desk | AL8: NIK | AM8: Name*_ | AO8: {=_xlfn.DROP(_xlfn.REDUCE("", (Sample_Pending[Stockpile]), _xlfn.LAMBDA(_xlpm.matriks,_xlpm.p, _xlfn.VSTACK(_xlpm.matriks, _xlfn.TOROW(IFERROR(_xlfn.UNIQUE(_xlfn._xlws.SORT(_xlfn._xlws.FILTER(Pile_area[pile_id], (Pile_area[stockpile] = _xlpm.p)*(Pile_area[pile_id]>0)))), ""))))), 1)} -> S5_01 | AP8: S5_06 | AQ8: S5_06_02A | AR8: S5_07 | AS8: S5_12_02 | AT8: S5_13 | AU8: S5_14 | AV8: S5_15 | AW8: S5_16 | AX8: S5_17 | AY8: S5_18 | AZ8: S5_19 | BA8: S5_20 | BB8: S5_21 | BC8: S5_22 | BD8: S5_23 | BE8: S5_24 | BF8: S5_25 | BG8: S5_26 | BH8: S5_27 | BI8: S5_28 | BJ8: S5_29 | BK8: S5_30 | BL8: S5_31 | BM8: S5_32 | BN8: S5_33 | BO8: S5_34 | BP8: S5_35 | BQ8: S5_36 | BR8: S5_37 | BS8: S5_38 | BT8: S5_39 | BU8: S5_40 | BV8: S5_41 | BW8: S5_42 | BX8: S5_43 | BY8: S5_44 | BZ8: S5_45 | CA8: S5_46 | CB8: S5_47 | CC8: S5_48 | CD8: S5_49 | CE8: S5_50 | CF8: S5_51 | CG8: S5_52 | CH8: S5_53 | CI8: S5_54 | CJ8: S5_55 | CK8: S5_56 | CL8: S5_57 | CM8: S5_58 | CN8: S5_59 | CO8: S5_60 | CP8: S5_61 | CQ8: S5_62 | CR8: S5_63 | CS8: S5_64 | CT8: S5_65 | CU8: S5_66 | CV8: S5_67 | CW8: S5_68 | CX8: S5_69 | CY8: S5_70 | CZ8: S5_71 | DA8: S5_72 | DB8: S5_73 | DC8: S5_74 | DD8: S5_75 | DE8: S5_76 | DF8: S5_77 | DG8: S5_79 | DH8: S5_80 | DI8: S5_81 | DJ8: S5_82 | DK8: S5_83 | DL8: S5_84 | DM8: S5_85 | DN8: S5_86 | DO8: S5_87 | DP8: S5_88 | DQ8: S5_89 | DR8: S5_90 | DS8: S5_91 | DT8: S5_92 | DU8: S5_93 | DV8: S5_L01 | DW8: S5_L02 | DX8: S5_L03 | DY8: S5_L04 | DZ8: S5_L05 | EA8: S5_L06 | EB8: S5_L07 | EC8: S5_L08
D9: C_05 | G9: SCM0627 | H9: Wahyudin Madilao | M9: SS_05 | N9: S5_88 | O9: 68 | P9: 16 | Q9: Cont | AD9: SAP | AE9: BR1/02 | AF9: 1 | AH9: 46211 | AI9: D | AJ9: BR1/SH_01 | AL9: SCM0333 | AM9: Raharjo Rahman | AO9: S5_01 | AP9: S5_06 | AQ9: S5_06_02A | AR9: S5_07 | AS9: S5_12_02 | AT9: S5_13 | AU9: S5_14 | AV9: S5_15 | AW9: S5_16 | AX9: S5_17 | AY9: S5_18 | AZ9: S5_19 | BA9: S5_20 | BB9: S5_21 | BC9: S5_22 | BD9: S5_23 | BE9: S5_24 | BF9: S5_25 | BG9: S5_26 | BH9: S5_27 | BI9: S5_28 | BJ9: S5_29 | BK9: S5_30 | BL9: S5_31 | BM9: S5_32 | BN9: S5_33 | BO9: S5_34 | BP9: S5_35 | BQ9: S5_36 | BR9: S5_37 | BS9: S5_38 | BT9: S5_39 | BU9: S5_40 | BV9: S5_41 | BW9: S5_42 | BX9: S5_43 | BY9: S5_44 | BZ9: S5_45 | CA9: S5_46 | CB9: S5_47 | CC9: S5_48 | CD9: S5_49 | CE9: S5_50 | CF9: S5_51 | CG9: S5_52 | CH9: S5_53 | CI9: S5_54 | CJ9: S5_55 | CK9: S5_56 | CL9: S5_57 | CM9: S5_58 | CN9: S5_59 | CO9: S5_60 | CP9: S5_61 | CQ9: S5_62 | CR9: S5_63 | CS9: S5_64 | CT9: S5_65 | CU9: S5_66 | CV9: S5_67 | CW9: S5_68 | CX9: S5_69 | CY9: S5_70 | CZ9: S5_71 | DA9: S5_72 | DB9: S5_73 | DC9: S5_74 | DD9: S5_75 | DE9: S5_76 | DF9: S5_77 | DG9: S5_79 | DH9: S5_80 | DI9: S5_81 | DJ9: S5_82 | DK9: S5_83 | DL9: S5_84 | DM9: S5_85 | DN9: S5_86 | DO9: S5_87 | DP9: S5_88 | DQ9: S5_89 | DR9: S5_90 | DS9: S5_91 | DT9: S5_92 | DU9: S5_93 | DV9: S5_L01 | DW9: S5_L02 | DX9: S5_L03 | DY9: S5_L04 | DZ9: S5_L05 | EA9: S5_L06 | EB9: S5_L07 | EC9: S5_L08
D10: C_06 | M10: BR-C_03 | N10: BR-C3_L10 | O10: 5 | P10: 66 | Q10: Cont | AD10: LIM | AE10: BR1/03 | AF10: 1 | AH10: 46211 | AI10: D | AJ10: BR1/SH_01 | AL10: SCM0627 | AM10: Wahyudin Madilao | AO10: BR-C3_L08 | AP10: BR-C3_L09 | AQ10: BR-C3_L10 | AR10: BR-C3_S05 | AS10: BR-C3B_S14 | AT10: #N/A | AU10: #N/A | AV10: #N/A | AW10: #N/A | AX10: #N/A | AY10: #N/A | AZ10: #N/A | BA10: #N/A | BB10: #N/A | BC10: #N/A | BD10: #N/A | BE10: #N/A | BF10: #N/A | BG10: #N/A | BH10: #N/A | BI10: #N/A | BJ10: #N/A | BK10: #N/A | BL10: #N/A | BM10: #N/A | BN10: #N/A | BO10: #N/A | BP10: #N/A | BQ10: #N/A | BR10: #N/A | BS10: #N/A | BT10: #N/A | BU10: #N/A | BV10: #N/A | BW10: #N/A | BX10: #N/A | BY10: #N/A | BZ10: #N/A | CA10: #N/A | CB10: #N/A | CC10: #N/A | CD10: #N/A | CE10: #N/A | CF10: #N/A | CG10: #N/A | CH10: #N/A | CI10: #N/A | CJ10: #N/A | CK10: #N/A | CL10: #N/A | CM10: #N/A | CN10: #N/A | CO10: #N/A | CP10: #N/A | CQ10: #N/A | CR10: #N/A | CS10: #N/A | CT10: #N/A | CU10: #N/A | CV10: #N/A | CW10: #N/A | CX10: #N/A | CY10: #N/A | CZ10: #N/A | DA10: #N/A | DB10: #N/A | DC10: #N/A | DD10: #N/A | DE10: #N/A | DF10: #N/A | DG10: #N/A | DH10: #N/A | DI10: #N/A | DJ10: #N/A | DK10: #N/A | DL10: #N/A | DM10: #N/A | DN10: #N/A | DO10: #N/A | DP10: #N/A | DQ10: #N/A | DR10: #N/A | DS10: #N/A | DT10: #N/A | DU10: #N/A | DV10: #N/A | DW10: #N/A | DX10: #N/A | DY10: #N/A | DZ10: #N/A | EA10: #N/A | EB10: #N/A | EC10: #N/A
D11: C_10 | M11: SS_05 | N11: S5_77 | O11: 40 | P11: 18 | Q11: Cont | AD11: SAP | AE11: BR1/04 | AF11: 1 | AH11: 46211 | AI11: D | AJ11: BR1/SH_01 | AK11: Sampler | AL11: 260225 | AM11: Andri Tani Kusuma | AO11: S5_01 | AP11: S5_06 | AQ11: S5_06_02A | AR11: S5_07 | AS11: S5_12_02 | AT11: S5_13 | AU11: S5_14 | AV11: S5_15 | AW11: S5_16 | AX11: S5_17 | AY11: S5_18 | AZ11: S5_19 | BA11: S5_20 | BB11: S5_21 | BC11: S5_22 | BD11: S5_23 | BE11: S5_24 | BF11: S5_25 | BG11: S5_26 | BH11: S5_27 | BI11: S5_28 | BJ11: S5_29 | BK11: S5_30 | BL11: S5_31 | BM11: S5_32 | BN11: S5_33 | BO11: S5_34 | BP11: S5_35 | BQ11: S5_36 | BR11: S5_37 | BS11: S5_38 | BT11: S5_39 | BU11: S5_40 | BV11: S5_41 | BW11: S5_42 | BX11: S5_43 | BY11: S5_44 | BZ11: S5_45 | CA11: S5_46 | CB11: S5_47 | CC11: S5_48 | CD11: S5_49 | CE11: S5_50 | CF11: S5_51 | CG11: S5_52 | CH11: S5_53 | CI11: S5_54 | CJ11: S5_55 | CK11: S5_56 | CL11: S5_57 | CM11: S5_58 | CN11: S5_59 | CO11: S5_60 | CP11: S5_61 | CQ11: S5_62 | CR11: S5_63 | CS11: S5_64 | CT11: S5_65 | CU11: S5_66 | CV11: S5_67 | CW11: S5_68 | CX11: S5_69 | CY11: S5_70 | CZ11: S5_71 | DA11: S5_72 | DB11: S5_73 | DC11: S5_74 | DD11: S5_75 | DE11: S5_76 | DF11: S5_77 | DG11: S5_79 | DH11: S5_80 | DI11: S5_81 | DJ11: S5_82 | DK11: S5_83 | DL11: S5_84 | DM11: S5_85 | DN11: S5_86 | DO11: S5_87 | DP11: S5_88 | DQ11: S5_89 | DR11: S5_90 | DS11: S5_91 | DT11: S5_92 | DU11: S5_93 | DV11: S5_L01 | DW11: S5_L02 | DX11: S5_L03 | DY11: S5_L04 | DZ11: S5_L05 | EA11: S5_L06 | EB11: S5_L07 | EC11: S5_L08
D12: C_12 | M12: SS_05 | N12: S5_77 | O12: 36 | P12: 3 | Q12: Cont | AD12: SAP | AE12: BR1/05 | AF12: 1 | AO12: S5_01 | AP12: S5_06 | AQ12: S5_06_02A | AR12: S5_07 | AS12: S5_12_02 | AT12: S5_13 | AU12: S5_14 | AV12: S5_15 | AW12: S5_16 | AX12: S5_17 | AY12: S5_18 | AZ12: S5_19 | BA12: S5_20 | BB12: S5_21 | BC12: S5_22 | BD12: S5_23 | BE12: S5_24 | BF12: S5_25 | BG12: S5_26 | BH12: S5_27 | BI12: S5_28 | BJ12: S5_29 | BK12: S5_30 | BL12: S5_31 | BM12: S5_32 | BN12: S5_33 | BO12: S5_34 | BP12: S5_35 | BQ12: S5_36 | BR12: S5_37 | BS12: S5_38 | BT12: S5_39 | BU12: S5_40 | BV12: S5_41 | BW12: S5_42 | BX12: S5_43 | BY12: S5_44 | BZ12: S5_45 | CA12: S5_46 | CB12: S5_47 | CC12: S5_48 | CD12: S5_49 | CE12: S5_50 | CF12: S5_51 | CG12: S5_52 | CH12: S5_53 | CI12: S5_54 | CJ12: S5_55 | CK12: S5_56 | CL12: S5_57 | CM12: S5_58 | CN12: S5_59 | CO12: S5_60 | CP12: S5_61 | CQ12: S5_62 | CR12: S5_63 | CS12: S5_64 | CT12: S5_65 | CU12: S5_66 | CV12: S5_67 | CW12: S5_68 | CX12: S5_69 | CY12: S5_70 | CZ12: S5_71 | DA12: S5_72 | DB12: S5_73 | DC12: S5_74 | DD12: S5_75 | DE12: S5_76 | DF12: S5_77 | DG12: S5_79 | DH12: S5_80 | DI12: S5_81 | DJ12: S5_82 | DK12: S5_83 | DL12: S5_84 | DM12: S5_85 | DN12: S5_86 | DO12: S5_87 | DP12: S5_88 | DQ12: S5_89 | DR12: S5_90 | DS12: S5_91 | DT12: S5_92 | DU12: S5_93 | DV12: S5_L01 | DW12: S5_L02 | DX12: S5_L03 | DY12: S5_L04 | DZ12: S5_L05 | EA12: S5_L06 | EB12: S5_L07 | EC12: S5_L08
D13: LS_01 | M13: BR-C_03 | N13: BR-C3_L10 | O13: 6 | P13: 12 | Q13: Cont | AD13: LIM | AO13: BR-C3_L08 | AP13: BR-C3_L09 | AQ13: BR-C3_L10 | AR13: BR-C3_S05 | AS13: BR-C3B_S14 | AT13: #N/A | AU13: #N/A | AV13: #N/A | AW13: #N/A | AX13: #N/A | AY13: #N/A | AZ13: #N/A | BA13: #N/A | BB13: #N/A | BC13: #N/A | BD13: #N/A | BE13: #N/A | BF13: #N/A | BG13: #N/A | BH13: #N/A | BI13: #N/A | BJ13: #N/A | BK13: #N/A | BL13: #N/A | BM13: #N/A | BN13: #N/A | BO13: #N/A | BP13: #N/A | BQ13: #N/A | BR13: #N/A | BS13: #N/A | BT13: #N/A | BU13: #N/A | BV13: #N/A | BW13: #N/A | BX13: #N/A | BY13: #N/A | BZ13: #N/A | CA13: #N/A | CB13: #N/A | CC13: #N/A | CD13: #N/A | CE13: #N/A | CF13: #N/A | CG13: #N/A | CH13: #N/A | CI13: #N/A | CJ13: #N/A | CK13: #N/A | CL13: #N/A | CM13: #N/A | CN13: #N/A | CO13: #N/A | CP13: #N/A | CQ13: #N/A | CR13: #N/A | CS13: #N/A | CT13: #N/A | CU13: #N/A | CV13: #N/A | CW13: #N/A | CX13: #N/A | CY13: #N/A | CZ13: #N/A | DA13: #N/A | DB13: #N/A | DC13: #N/A | DD13: #N/A | DE13: #N/A | DF13: #N/A | DG13: #N/A | DH13: #N/A | DI13: #N/A | DJ13: #N/A | DK13: #N/A | DL13: #N/A | DM13: #N/A | DN13: #N/A | DO13: #N/A | DP13: #N/A | DQ13: #N/A | DR13: #N/A | DS13: #N/A | DT13: #N/A | DU13: #N/A | DV13: #N/A | DW13: #N/A | DX13: #N/A | DY13: #N/A | DZ13: #N/A | EA13: #N/A | EB13: #N/A | EC13: #N/A
D14: LS_02 | M14: BR-C_12 | N14: BR-C12_L12 | O14: 3 | P14: 90 | Q14: Cont | AD14: LIM | AO14: BR-C12_L10 | AP14: BR-C12_L11 | AQ14: BR-C12_L12 | AR14: #N/A | AS14: #N/A | AT14: #N/A | AU14: #N/A | AV14: #N/A | AW14: #N/A | AX14: #N/A | AY14: #N/A | AZ14: #N/A | BA14: #N/A | BB14: #N/A | BC14: #N/A | BD14: #N/A | BE14: #N/A | BF14: #N/A | BG14: #N/A | BH14: #N/A | BI14: #N/A | BJ14: #N/A | BK14: #N/A | BL14: #N/A | BM14: #N/A | BN14: #N/A | BO14: #N/A | BP14: #N/A | BQ14: #N/A | BR14: #N/A | BS14: #N/A | BT14: #N/A | BU14: #N/A | BV14: #N/A | BW14: #N/A | BX14: #N/A | BY14: #N/A | BZ14: #N/A | CA14: #N/A | CB14: #N/A | CC14: #N/A | CD14: #N/A | CE14: #N/A | CF14: #N/A | CG14: #N/A | CH14: #N/A | CI14: #N/A | CJ14: #N/A | CK14: #N/A | CL14: #N/A | CM14: #N/A | CN14: #N/A | CO14: #N/A | CP14: #N/A | CQ14: #N/A | CR14: #N/A | CS14: #N/A | CT14: #N/A | CU14: #N/A | CV14: #N/A | CW14: #N/A | CX14: #N/A | CY14: #N/A | CZ14: #N/A | DA14: #N/A | DB14: #N/A | DC14: #N/A | DD14: #N/A | DE14: #N/A | DF14: #N/A | DG14: #N/A | DH14: #N/A | DI14: #N/A | DJ14: #N/A | DK14: #N/A | DL14: #N/A | DM14: #N/A | DN14: #N/A | DO14: #N/A | DP14: #N/A | DQ14: #N/A | DR14: #N/A | DS14: #N/A | DT14: #N/A | DU14: #N/A | DV14: #N/A | DW14: #N/A | DX14: #N/A | DY14: #N/A | DZ14: #N/A | EA14: #N/A | EB14: #N/A | EC14: #N/A
D15: LS_03 | M15: BR-C_06 | N15: BR-C6_S10 | O15: 32 | P15: 1 | Q15: Cont | AD15: SAP | AO15: BR-C6_L22 | AP15: BR-C6_L23 | AQ15: BR-C6_S07 | AR15: BR-C6_S08 | AS15: BR-C6_S10 | AT15: BR-C6C_S06 | AU15: BR-C6C_S07 | AV15: BR-C6D_S06 | AW15: BR-C6D_S16 | AX15: #N/A | AY15: #N/A | AZ15: #N/A | BA15: #N/A | BB15: #N/A | BC15: #N/A | BD15: #N/A | BE15: #N/A | BF15: #N/A | BG15: #N/A | BH15: #N/A | BI15: #N/A | BJ15: #N/A | BK15: #N/A | BL15: #N/A | BM15: #N/A | BN15: #N/A | BO15: #N/A | BP15: #N/A | BQ15: #N/A | BR15: #N/A | BS15: #N/A | BT15: #N/A | BU15: #N/A | BV15: #N/A | BW15: #N/A | BX15: #N/A | BY15: #N/A | BZ15: #N/A | CA15: #N/A | CB15: #N/A | CC15: #N/A | CD15: #N/A | CE15: #N/A | CF15: #N/A | CG15: #N/A | CH15: #N/A | CI15: #N/A | CJ15: #N/A | CK15: #N/A | CL15: #N/A | CM15: #N/A | CN15: #N/A | CO15: #N/A | CP15: #N/A | CQ15: #N/A | CR15: #N/A | CS15: #N/A | CT15: #N/A | CU15: #N/A | CV15: #N/A | CW15: #N/A | CX15: #N/A | CY15: #N/A | CZ15: #N/A | DA15: #N/A | DB15: #N/A | DC15: #N/A | DD15: #N/A | DE15: #N/A | DF15: #N/A | DG15: #N/A | DH15: #N/A | DI15: #N/A | DJ15: #N/A | DK15: #N/A | DL15: #N/A | DM15: #N/A | DN15: #N/A | DO15: #N/A | DP15: #N/A | DQ15: #N/A | DR15: #N/A | DS15: #N/A | DT15: #N/A | DU15: #N/A | DV15: #N/A | DW15: #N/A | DX15: #N/A | DY15: #N/A | DZ15: #N/A | EA15: #N/A | EB15: #N/A | EC15: #N/A
D16: LS_04 | M16: SS_05 | N16: S5_88 | O16: 59 | P16: 7 | Q16: Cont | AD16: SAP | AO16: S5_01 | AP16: S5_06 | AQ16: S5_06_02A | AR16: S5_07 | AS16: S5_12_02 | AT16: S5_13 | AU16: S5_14 | AV16: S5_15 | AW16: S5_16 | AX16: S5_17 | AY16: S5_18 | AZ16: S5_19 | BA16: S5_20 | BB16: S5_21 | BC16: S5_22 | BD16: S5_23 | BE16: S5_24 | BF16: S5_25 | BG16: S5_26 | BH16: S5_27 | BI16: S5_28 | BJ16: S5_29 | BK16: S5_30 | BL16: S5_31 | BM16: S5_32 | BN16: S5_33 | BO16: S5_34 | BP16: S5_35 | BQ16: S5_36 | BR16: S5_37 | BS16: S5_38 | BT16: S5_39 | BU16: S5_40 | BV16: S5_41 | BW16: S5_42 | BX16: S5_43 | BY16: S5_44 | BZ16: S5_45 | CA16: S5_46 | CB16: S5_47 | CC16: S5_48 | CD16: S5_49 | CE16: S5_50 | CF16: S5_51 | CG16: S5_52 | CH16: S5_53 | CI16: S5_54 | CJ16: S5_55 | CK16: S5_56 | CL16: S5_57 | CM16: S5_58 | CN16: S5_59 | CO16: S5_60 | CP16: S5_61 | CQ16: S5_62 | CR16: S5_63 | CS16: S5_64 | CT16: S5_65 | CU16: S5_66 | CV16: S5_67 | CW16: S5_68 | CX16: S5_69 | CY16: S5_70 | CZ16: S5_71 | DA16: S5_72 | DB16: S5_73 | DC16: S5_74 | DD16: S5_75 | DE16: S5_76 | DF16: S5_77 | DG16: S5_79 | DH16: S5_80 | DI16: S5_81 | DJ16: S5_82 | DK16: S5_83 | DL16: S5_84 | DM16: S5_85 | DN16: S5_86 | DO16: S5_87 | DP16: S5_88 | DQ16: S5_89 | DR16: S5_90 | DS16: S5_91 | DT16: S5_92 | DU16: S5_93 | DV16: S5_L01 | DW16: S5_L02 | DX16: S5_L03 | DY16: S5_L04 | DZ16: S5_L05 | EA16: S5_L06 | EB16: S5_L07 | EC16: S5_L08
D17: LS_05 | M17: LS_18 | N17: L18_S09 | O17: 31 | P17: 18 | Q17: Cont | AD17: SAP | AO17: L18_01 | AP17: L18_03 | AQ17: L18_04 | AR17: L18_05 | AS17: L18_06 | AT17: L18_07 | AU17: L18_08 | AV17: L18_09 | AW17: L18_10 | AX17: L18_11 | AY17: L18_S01 | AZ17: L18_S02 | BA17: L18_S03 | BB17: L18_S04 | BC17: L18_S05 | BD17: L18_S06 | BE17: L18_S07 | BF17: L18_S09 | BG17: #N/A | BH17: #N/A | BI17: #N/A | BJ17: #N/A | BK17: #N/A | BL17: #N/A | BM17: #N/A | BN17: #N/A | BO17: #N/A | BP17: #N/A | BQ17: #N/A | BR17: #N/A | BS17: #N/A | BT17: #N/A | BU17: #N/A | BV17: #N/A | BW17: #N/A | BX17: #N/A | BY17: #N/A | BZ17: #N/A | CA17: #N/A | CB17: #N/A | CC17: #N/A | CD17: #N/A | CE17: #N/A | CF17: #N/A | CG17: #N/A | CH17: #N/A | CI17: #N/A | CJ17: #N/A | CK17: #N/A | CL17: #N/A | CM17: #N/A | CN17: #N/A | CO17: #N/A | CP17: #N/A | CQ17: #N/A | CR17: #N/A | CS17: #N/A | CT17: #N/A | CU17: #N/A | CV17: #N/A | CW17: #N/A | CX17: #N/A | CY17: #N/A | CZ17: #N/A | DA17: #N/A | DB17: #N/A | DC17: #N/A | DD17: #N/A | DE17: #N/A | DF17: #N/A | DG17: #N/A | DH17: #N/A | DI17: #N/A | DJ17: #N/A | DK17: #N/A | DL17: #N/A | DM17: #N/A | DN17: #N/A | DO17: #N/A | DP17: #N/A | DQ17: #N/A | DR17: #N/A | DS17: #N/A | DT17: #N/A | DU17: #N/A | DV17: #N/A | DW17: #N/A | DX17: #N/A | DY17: #N/A | DZ17: #N/A | EA17: #N/A | EB17: #N/A | EC17: #N/A
D18: LS_07 | G18: Job | H18: NIK | I18: Name | M18: BR-C_06 | N18: BR-C6_S10 | O18: 31 | P18: 10 | Q18: Cont | AD18: SAP | AO18: BR-C6_L22 | AP18: BR-C6_L23 | AQ18: BR-C6_S07 | AR18: BR-C6_S08 | AS18: BR-C6_S10 | AT18: BR-C6C_S06 | AU18: BR-C6C_S07 | AV18: BR-C6D_S06 | AW18: BR-C6D_S16 | AX18: #N/A | AY18: #N/A | AZ18: #N/A | BA18: #N/A | BB18: #N/A | BC18: #N/A | BD18: #N/A | BE18: #N/A | BF18: #N/A | BG18: #N/A | BH18: #N/A | BI18: #N/A | BJ18: #N/A | BK18: #N/A | BL18: #N/A | BM18: #N/A | BN18: #N/A | BO18: #N/A | BP18: #N/A | BQ18: #N/A | BR18: #N/A | BS18: #N/A | BT18: #N/A | BU18: #N/A | BV18: #N/A | BW18: #N/A | BX18: #N/A | BY18: #N/A | BZ18: #N/A | CA18: #N/A | CB18: #N/A | CC18: #N/A | CD18: #N/A | CE18: #N/A | CF18: #N/A | CG18: #N/A | CH18: #N/A | CI18: #N/A | CJ18: #N/A | CK18: #N/A | CL18: #N/A | CM18: #N/A | CN18: #N/A | CO18: #N/A | CP18: #N/A | CQ18: #N/A | CR18: #N/A | CS18: #N/A | CT18: #N/A | CU18: #N/A | CV18: #N/A | CW18: #N/A | CX18: #N/A | CY18: #N/A | CZ18: #N/A | DA18: #N/A | DB18: #N/A | DC18: #N/A | DD18: #N/A | DE18: #N/A | DF18: #N/A | DG18: #N/A | DH18: #N/A | DI18: #N/A | DJ18: #N/A | DK18: #N/A | DL18: #N/A | DM18: #N/A | DN18: #N/A | DO18: #N/A | DP18: #N/A | DQ18: #N/A | DR18: #N/A | DS18: #N/A | DT18: #N/A | DU18: #N/A | DV18: #N/A | DW18: #N/A | DX18: #N/A | DY18: #N/A | DZ18: #N/A | EA18: #N/A | EB18: #N/A | EC18: #N/A
D19: LS_08 | G19: Sampler | H19: 260225 | I19: {=IF(Person4[NIK]="","",_xlfn.XLOOKUP(Person4[NIK],Emply_Crew[NIK],Emply_Crew[EMP_NAME]))} -> Andri Tani Kusuma | M19: BR-C_12 | N19: BR-C12_L12 | O19: 4 | P19: 79 | Q19: Cont | AD19: LIM | AO19: BR-C12_L10 | AP19: BR-C12_L11 | AQ19: BR-C12_L12 | AR19: #N/A | AS19: #N/A | AT19: #N/A | AU19: #N/A | AV19: #N/A | AW19: #N/A | AX19: #N/A | AY19: #N/A | AZ19: #N/A | BA19: #N/A | BB19: #N/A | BC19: #N/A | BD19: #N/A | BE19: #N/A | BF19: #N/A | BG19: #N/A | BH19: #N/A | BI19: #N/A | BJ19: #N/A | BK19: #N/A | BL19: #N/A | BM19: #N/A | BN19: #N/A | BO19: #N/A | BP19: #N/A | BQ19: #N/A | BR19: #N/A | BS19: #N/A | BT19: #N/A | BU19: #N/A | BV19: #N/A | BW19: #N/A | BX19: #N/A | BY19: #N/A | BZ19: #N/A | CA19: #N/A | CB19: #N/A | CC19: #N/A | CD19: #N/A | CE19: #N/A | CF19: #N/A | CG19: #N/A | CH19: #N/A | CI19: #N/A | CJ19: #N/A | CK19: #N/A | CL19: #N/A | CM19: #N/A | CN19: #N/A | CO19: #N/A | CP19: #N/A | CQ19: #N/A | CR19: #N/A | CS19: #N/A | CT19: #N/A | CU19: #N/A | CV19: #N/A | CW19: #N/A | CX19: #N/A | CY19: #N/A | CZ19: #N/A | DA19: #N/A | DB19: #N/A | DC19: #N/A | DD19: #N/A | DE19: #N/A | DF19: #N/A | DG19: #N/A | DH19: #N/A | DI19: #N/A | DJ19: #N/A | DK19: #N/A | DL19: #N/A | DM19: #N/A | DN19: #N/A | DO19: #N/A | DP19: #N/A | DQ19: #N/A | DR19: #N/A | DS19: #N/A | DT19: #N/A | DU19: #N/A | DV19: #N/A | DW19: #N/A | DX19: #N/A | DY19: #N/A | DZ19: #N/A | EA19: #N/A | EB19: #N/A | EC19: #N/A
D20: LS_09 | M20: BR-C_06 | N20: BR-C6_S10 | O20: 22 | P20: 13 | Q20: Cont | AD20: SAP | AO20: BR-C6_L22 | AP20: BR-C6_L23 | AQ20: BR-C6_S07 | AR20: BR-C6_S08 | AS20: BR-C6_S10 | AT20: BR-C6C_S06 | AU20: BR-C6C_S07 | AV20: BR-C6D_S06 | AW20: BR-C6D_S16 | AX20: #N/A | AY20: #N/A | AZ20: #N/A | BA20: #N/A | BB20: #N/A | BC20: #N/A | BD20: #N/A | BE20: #N/A | BF20: #N/A | BG20: #N/A | BH20: #N/A | BI20: #N/A | BJ20: #N/A | BK20: #N/A | BL20: #N/A | BM20: #N/A | BN20: #N/A | BO20: #N/A | BP20: #N/A | BQ20: #N/A | BR20: #N/A | BS20: #N/A | BT20: #N/A | BU20: #N/A | BV20: #N/A | BW20: #N/A | BX20: #N/A | BY20: #N/A | BZ20: #N/A | CA20: #N/A | CB20: #N/A | CC20: #N/A | CD20: #N/A | CE20: #N/A | CF20: #N/A | CG20: #N/A | CH20: #N/A | CI20: #N/A | CJ20: #N/A | CK20: #N/A | CL20: #N/A | CM20: #N/A | CN20: #N/A | CO20: #N/A | CP20: #N/A | CQ20: #N/A | CR20: #N/A | CS20: #N/A | CT20: #N/A | CU20: #N/A | CV20: #N/A | CW20: #N/A | CX20: #N/A | CY20: #N/A | CZ20: #N/A | DA20: #N/A | DB20: #N/A | DC20: #N/A | DD20: #N/A | DE20: #N/A | DF20: #N/A | DG20: #N/A | DH20: #N/A | DI20: #N/A | DJ20: #N/A | DK20: #N/A | DL20: #N/A | DM20: #N/A | DN20: #N/A | DO20: #N/A | DP20: #N/A | DQ20: #N/A | DR20: #N/A | DS20: #N/A | DT20: #N/A | DU20: #N/A | DV20: #N/A | DW20: #N/A | DX20: #N/A | DY20: #N/A | DZ20: #N/A | EA20: #N/A | EB20: #N/A | EC20: #N/A
D21: LS_12 | M21: SS_05 | N21: S5_77 | O21: 42 | P21: 19 | Q21: Cont | AD21: SAP | AO21: S5_01 | AP21: S5_06 | AQ21: S5_06_02A | AR21: S5_07 | AS21: S5_12_02 | AT21: S5_13 | AU21: S5_14 | AV21: S5_15 | AW21: S5_16 | AX21: S5_17 | AY21: S5_18 | AZ21: S5_19 | BA21: S5_20 | BB21: S5_21 | BC21: S5_22 | BD21: S5_23 | BE21: S5_24 | BF21: S5_25 | BG21: S5_26 | BH21: S5_27 | BI21: S5_28 | BJ21: S5_29 | BK21: S5_30 | BL21: S5_31 | BM21: S5_32 | BN21: S5_33 | BO21: S5_34 | BP21: S5_35 | BQ21: S5_36 | BR21: S5_37 | BS21: S5_38 | BT21: S5_39 | BU21: S5_40 | BV21: S5_41 | BW21: S5_42 | BX21: S5_43 | BY21: S5_44 | BZ21: S5_45 | CA21: S5_46 | CB21: S5_47 | CC21: S5_48 | CD21: S5_49 | CE21: S5_50 | CF21: S5_51 | CG21: S5_52 | CH21: S5_53 | CI21: S5_54 | CJ21: S5_55 | CK21: S5_56 | CL21: S5_57 | CM21: S5_58 | CN21: S5_59 | CO21: S5_60 | CP21: S5_61 | CQ21: S5_62 | CR21: S5_63 | CS21: S5_64 | CT21: S5_65 | CU21: S5_66 | CV21: S5_67 | CW21: S5_68 | CX21: S5_69 | CY21: S5_70 | CZ21: S5_71 | DA21: S5_72 | DB21: S5_73 | DC21: S5_74 | DD21: S5_75 | DE21: S5_76 | DF21: S5_77 | DG21: S5_79 | DH21: S5_80 | DI21: S5_81 | DJ21: S5_82 | DK21: S5_83 | DL21: S5_84 | DM21: S5_85 | DN21: S5_86 | DO21: S5_87 | DP21: S5_88 | DQ21: S5_89 | DR21: S5_90 | DS21: S5_91 | DT21: S5_92 | DU21: S5_93 | DV21: S5_L01 | DW21: S5_L02 | DX21: S5_L03 | DY21: S5_L04 | DZ21: S5_L05 | EA21: S5_L06 | EB21: S5_L07 | EC21: S5_L08
D22: LS_14 | M22: BR-C_06 | N22: BR-C6_S10 | O22: 12 | P22: 7 | Q22: Cont | AD22: SAP | AO22: BR-C6_L22 | AP22: BR-C6_L23 | AQ22: BR-C6_S07 | AR22: BR-C6_S08 | AS22: BR-C6_S10 | AT22: BR-C6C_S06 | AU22: BR-C6C_S07 | AV22: BR-C6D_S06 | AW22: BR-C6D_S16 | AX22: #N/A | AY22: #N/A | AZ22: #N/A | BA22: #N/A | BB22: #N/A | BC22: #N/A | BD22: #N/A | BE22: #N/A | BF22: #N/A | BG22: #N/A | BH22: #N/A | BI22: #N/A | BJ22: #N/A | BK22: #N/A | BL22: #N/A | BM22: #N/A | BN22: #N/A | BO22: #N/A | BP22: #N/A | BQ22: #N/A | BR22: #N/A | BS22: #N/A | BT22: #N/A | BU22: #N/A | BV22: #N/A | BW22: #N/A | BX22: #N/A | BY22: #N/A | BZ22: #N/A | CA22: #N/A | CB22: #N/A | CC22: #N/A | CD22: #N/A | CE22: #N/A | CF22: #N/A | CG22: #N/A | CH22: #N/A | CI22: #N/A | CJ22: #N/A | CK22: #N/A | CL22: #N/A | CM22: #N/A | CN22: #N/A | CO22: #N/A | CP22: #N/A | CQ22: #N/A | CR22: #N/A | CS22: #N/A | CT22: #N/A | CU22: #N/A | CV22: #N/A | CW22: #N/A | CX22: #N/A | CY22: #N/A | CZ22: #N/A | DA22: #N/A | DB22: #N/A | DC22: #N/A | DD22: #N/A | DE22: #N/A | DF22: #N/A | DG22: #N/A | DH22: #N/A | DI22: #N/A | DJ22: #N/A | DK22: #N/A | DL22: #N/A | DM22: #N/A | DN22: #N/A | DO22: #N/A | DP22: #N/A | DQ22: #N/A | DR22: #N/A | DS22: #N/A | DT22: #N/A | DU22: #N/A | DV22: #N/A | DW22: #N/A | DX22: #N/A | DY22: #N/A | DZ22: #N/A | EA22: #N/A | EB22: #N/A | EC22: #N/A
D23: LS_15 | M23: LS_18 | N23: L18_S09 | O23: 25 | P23: 3 | Q23: Cont | AD23: SAP | AO23: L18_01 | AP23: L18_03 | AQ23: L18_04 | AR23: L18_05 | AS23: L18_06 | AT23: L18_07 | AU23: L18_08 | AV23: L18_09 | AW23: L18_10 | AX23: L18_11 | AY23: L18_S01 | AZ23: L18_S02 | BA23: L18_S03 | BB23: L18_S04 | BC23: L18_S05 | BD23: L18_S06 | BE23: L18_S07 | BF23: L18_S09 | BG23: #N/A | BH23: #N/A | BI23: #N/A | BJ23: #N/A | BK23: #N/A | BL23: #N/A | BM23: #N/A | BN23: #N/A | BO23: #N/A | BP23: #N/A | BQ23: #N/A | BR23: #N/A | BS23: #N/A | BT23: #N/A | BU23: #N/A | BV23: #N/A | BW23: #N/A | BX23: #N/A | BY23: #N/A | BZ23: #N/A | CA23: #N/A | CB23: #N/A | CC23: #N/A | CD23: #N/A | CE23: #N/A | CF23: #N/A | CG23: #N/A | CH23: #N/A | CI23: #N/A | CJ23: #N/A | CK23: #N/A | CL23: #N/A | CM23: #N/A | CN23: #N/A | CO23: #N/A | CP23: #N/A | CQ23: #N/A | CR23: #N/A | CS23: #N/A | CT23: #N/A | CU23: #N/A | CV23: #N/A | CW23: #N/A | CX23: #N/A | CY23: #N/A | CZ23: #N/A | DA23: #N/A | DB23: #N/A | DC23: #N/A | DD23: #N/A | DE23: #N/A | DF23: #N/A | DG23: #N/A | DH23: #N/A | DI23: #N/A | DJ23: #N/A | DK23: #N/A | DL23: #N/A | DM23: #N/A | DN23: #N/A | DO23: #N/A | DP23: #N/A | DQ23: #N/A | DR23: #N/A | DS23: #N/A | DT23: #N/A | DU23: #N/A | DV23: #N/A | DW23: #N/A | DX23: #N/A | DY23: #N/A | DZ23: #N/A | EA23: #N/A | EB23: #N/A | EC23: #N/A
D24: LS_16 | M24: SS_05 | N24: S5_88 | O24: 67 | P24: 15 | Q24: Cont | AD24: SAP | AO24: S5_01 | AP24: S5_06 | AQ24: S5_06_02A | AR24: S5_07 | AS24: S5_12_02 | AT24: S5_13 | AU24: S5_14 | AV24: S5_15 | AW24: S5_16 | AX24: S5_17 | AY24: S5_18 | AZ24: S5_19 | BA24: S5_20 | BB24: S5_21 | BC24: S5_22 | BD24: S5_23 | BE24: S5_24 | BF24: S5_25 | BG24: S5_26 | BH24: S5_27 | BI24: S5_28 | BJ24: S5_29 | BK24: S5_30 | BL24: S5_31 | BM24: S5_32 | BN24: S5_33 | BO24: S5_34 | BP24: S5_35 | BQ24: S5_36 | BR24: S5_37 | BS24: S5_38 | BT24: S5_39 | BU24: S5_40 | BV24: S5_41 | BW24: S5_42 | BX24: S5_43 | BY24: S5_44 | BZ24: S5_45 | CA24: S5_46 | CB24: S5_47 | CC24: S5_48 | CD24: S5_49 | CE24: S5_50 | CF24: S5_51 | CG24: S5_52 | CH24: S5_53 | CI24: S5_54 | CJ24: S5_55 | CK24: S5_56 | CL24: S5_57 | CM24: S5_58 | CN24: S5_59 | CO24: S5_60 | CP24: S5_61 | CQ24: S5_62 | CR24: S5_63 | CS24: S5_64 | CT24: S5_65 | CU24: S5_66 | CV24: S5_67 | CW24: S5_68 | CX24: S5_69 | CY24: S5_70 | CZ24: S5_71 | DA24: S5_72 | DB24: S5_73 | DC24: S5_74 | DD24: S5_75 | DE24: S5_76 | DF24: S5_77 | DG24: S5_79 | DH24: S5_80 | DI24: S5_81 | DJ24: S5_82 | DK24: S5_83 | DL24: S5_84 | DM24: S5_85 | DN24: S5_86 | DO24: S5_87 | DP24: S5_88 | DQ24: S5_89 | DR24: S5_90 | DS24: S5_91 | DT24: S5_92 | DU24: S5_93 | DV24: S5_L01 | DW24: S5_L02 | DX24: S5_L03 | DY24: S5_L04 | DZ24: S5_L05 | EA24: S5_L06 | EB24: S5_L07 | EC24: S5_L08
D25: LS_18 | M25: LS_18 | N25: L18_S09 | O25: 24 | P25: 10 | Q25: Cont | AD25: SAP | AO25: L18_01 | AP25: L18_03 | AQ25: L18_04 | AR25: L18_05 | AS25: L18_06 | AT25: L18_07 | AU25: L18_08 | AV25: L18_09 | AW25: L18_10 | AX25: L18_11 | AY25: L18_S01 | AZ25: L18_S02 | BA25: L18_S03 | BB25: L18_S04 | BC25: L18_S05 | BD25: L18_S06 | BE25: L18_S07 | BF25: L18_S09 | BG25: #N/A | BH25: #N/A | BI25: #N/A | BJ25: #N/A | BK25: #N/A | BL25: #N/A | BM25: #N/A | BN25: #N/A | BO25: #N/A | BP25: #N/A | BQ25: #N/A | BR25: #N/A | BS25: #N/A | BT25: #N/A | BU25: #N/A | BV25: #N/A | BW25: #N/A | BX25: #N/A | BY25: #N/A | BZ25: #N/A | CA25: #N/A | CB25: #N/A | CC25: #N/A | CD25: #N/A | CE25: #N/A | CF25: #N/A | CG25: #N/A | CH25: #N/A | CI25: #N/A | CJ25: #N/A | CK25: #N/A | CL25: #N/A | CM25: #N/A | CN25: #N/A | CO25: #N/A | CP25: #N/A | CQ25: #N/A | CR25: #N/A | CS25: #N/A | CT25: #N/A | CU25: #N/A | CV25: #N/A | CW25: #N/A | CX25: #N/A | CY25: #N/A | CZ25: #N/A | DA25: #N/A | DB25: #N/A | DC25: #N/A | DD25: #N/A | DE25: #N/A | DF25: #N/A | DG25: #N/A | DH25: #N/A | DI25: #N/A | DJ25: #N/A | DK25: #N/A | DL25: #N/A | DM25: #N/A | DN25: #N/A | DO25: #N/A | DP25: #N/A | DQ25: #N/A | DR25: #N/A | DS25: #N/A | DT25: #N/A | DU25: #N/A | DV25: #N/A | DW25: #N/A | DX25: #N/A | DY25: #N/A | DZ25: #N/A | EA25: #N/A | EB25: #N/A | EC25: #N/A
D26: LS_21 | M26: SS_05 | N26: S5_93 | O26: 6 | P26: 4 | Q26: Cont | AD26: SAP | AO26: S5_01 | AP26: S5_06 | AQ26: S5_06_02A | AR26: S5_07 | AS26: S5_12_02 | AT26: S5_13 | AU26: S5_14 | AV26: S5_15 | AW26: S5_16 | AX26: S5_17 | AY26: S5_18 | AZ26: S5_19 | BA26: S5_20 | BB26: S5_21 | BC26: S5_22 | BD26: S5_23 | BE26: S5_24 | BF26: S5_25 | BG26: S5_26 | BH26: S5_27 | BI26: S5_28 | BJ26: S5_29 | BK26: S5_30 | BL26: S5_31 | BM26: S5_32 | BN26: S5_33 | BO26: S5_34 | BP26: S5_35 | BQ26: S5_36 | BR26: S5_37 | BS26: S5_38 | BT26: S5_39 | BU26: S5_40 | BV26: S5_41 | BW26: S5_42 | BX26: S5_43 | BY26: S5_44 | BZ26: S5_45 | CA26: S5_46 | CB26: S5_47 | CC26: S5_48 | CD26: S5_49 | CE26: S5_50 | CF26: S5_51 | CG26: S5_52 | CH26: S5_53 | CI26: S5_54 | CJ26: S5_55 | CK26: S5_56 | CL26: S5_57 | CM26: S5_58 | CN26: S5_59 | CO26: S5_60 | CP26: S5_61 | CQ26: S5_62 | CR26: S5_63 | CS26: S5_64 | CT26: S5_65 | CU26: S5_66 | CV26: S5_67 | CW26: S5_68 | CX26: S5_69 | CY26: S5_70 | CZ26: S5_71 | DA26: S5_72 | DB26: S5_73 | DC26: S5_74 | DD26: S5_75 | DE26: S5_76 | DF26: S5_77 | DG26: S5_79 | DH26: S5_80 | DI26: S5_81 | DJ26: S5_82 | DK26: S5_83 | DL26: S5_84 | DM26: S5_85 | DN26: S5_86 | DO26: S5_87 | DP26: S5_88 | DQ26: S5_89 | DR26: S5_90 | DS26: S5_91 | DT26: S5_92 | DU26: S5_93 | DV26: S5_L01 | DW26: S5_L02 | DX26: S5_L03 | DY26: S5_L04 | DZ26: S5_L05 | EA26: S5_L06 | EB26: S5_L07 | EC26: S5_L08
D27: SS_01 | M27: LS_09 | N27: L9_26 | O27: 2 | P27: 10 | Q27: Cont | AD27: LIM | AO27: L9_01 | AP27: L9_02 | AQ27: L9_04 | AR27: L9_05 | AS27: L9_06 | AT27: L9_07 | AU27: L9_08 | AV27: L9_09 | AW27: L9_10 | AX27: L9_11 | AY27: L9_12 | AZ27: L9_13 | BA27: L9_14 | BB27: L9_15 | BC27: L9_16 | BD27: L9_17 | BE27: L9_18 | BF27: L9_19 | BG27: L9_20 | BH27: L9_21 | BI27: L9_22 | BJ27: L9_23 | BK27: L9_24 | BL27: L9_26 | BM27: L9_S01 | BN27: L9_S02 | BO27: L9_S03 | BP27: L9_S04 | BQ27: #N/A | BR27: #N/A | BS27: #N/A | BT27: #N/A | BU27: #N/A | BV27: #N/A | BW27: #N/A | BX27: #N/A | BY27: #N/A | BZ27: #N/A | CA27: #N/A | CB27: #N/A | CC27: #N/A | CD27: #N/A | CE27: #N/A | CF27: #N/A | CG27: #N/A | CH27: #N/A | CI27: #N/A | CJ27: #N/A | CK27: #N/A | CL27: #N/A | CM27: #N/A | CN27: #N/A | CO27: #N/A | CP27: #N/A | CQ27: #N/A | CR27: #N/A | CS27: #N/A | CT27: #N/A | CU27: #N/A | CV27: #N/A | CW27: #N/A | CX27: #N/A | CY27: #N/A | CZ27: #N/A | DA27: #N/A | DB27: #N/A | DC27: #N/A | DD27: #N/A | DE27: #N/A | DF27: #N/A | DG27: #N/A | DH27: #N/A | DI27: #N/A | DJ27: #N/A | DK27: #N/A | DL27: #N/A | DM27: #N/A | DN27: #N/A | DO27: #N/A | DP27: #N/A | DQ27: #N/A | DR27: #N/A | DS27: #N/A | DT27: #N/A | DU27: #N/A | DV27: #N/A | DW27: #N/A | DX27: #N/A | DY27: #N/A | DZ27: #N/A | EA27: #N/A | EB27: #N/A | EC27: #N/A
D28: SS_02 | M28: LS_18 | N28: L18_S09 | O28: 32 | P28: 14 | Q28: Cont | AD28: SAP | AO28: L18_01 | AP28: L18_03 | AQ28: L18_04 | AR28: L18_05 | AS28: L18_06 | AT28: L18_07 | AU28: L18_08 | AV28: L18_09 | AW28: L18_10 | AX28: L18_11 | AY28: L18_S01 | AZ28: L18_S02 | BA28: L18_S03 | BB28: L18_S04 | BC28: L18_S05 | BD28: L18_S06 | BE28: L18_S07 | BF28: L18_S09 | BG28: #N/A | BH28: #N/A | BI28: #N/A | BJ28: #N/A | BK28: #N/A | BL28: #N/A | BM28: #N/A | BN28: #N/A | BO28: #N/A | BP28: #N/A | BQ28: #N/A | BR28: #N/A | BS28: #N/A | BT28: #N/A | BU28: #N/A | BV28: #N/A | BW28: #N/A | BX28: #N/A | BY28: #N/A | BZ28: #N/A | CA28: #N/A | CB28: #N/A | CC28: #N/A | CD28: #N/A | CE28: #N/A | CF28: #N/A | CG28: #N/A | CH28: #N/A | CI28: #N/A | CJ28: #N/A | CK28: #N/A | CL28: #N/A | CM28: #N/A | CN28: #N/A | CO28: #N/A | CP28: #N/A | CQ28: #N/A | CR28: #N/A | CS28: #N/A | CT28: #N/A | CU28: #N/A | CV28: #N/A | CW28: #N/A | CX28: #N/A | CY28: #N/A | CZ28: #N/A | DA28: #N/A | DB28: #N/A | DC28: #N/A | DD28: #N/A | DE28: #N/A | DF28: #N/A | DG28: #N/A | DH28: #N/A | DI28: #N/A | DJ28: #N/A | DK28: #N/A | DL28: #N/A | DM28: #N/A | DN28: #N/A | DO28: #N/A | DP28: #N/A | DQ28: #N/A | DR28: #N/A | DS28: #N/A | DT28: #N/A | DU28: #N/A | DV28: #N/A | DW28: #N/A | DX28: #N/A | DY28: #N/A | DZ28: #N/A | EA28: #N/A | EB28: #N/A | EC28: #N/A
D29: SS_03 | AP29: #N/A | AQ29: #N/A | AR29: #N/A | AS29: #N/A | AT29: #N/A | AU29: #N/A | AV29: #N/A | AW29: #N/A | AX29: #N/A | AY29: #N/A | AZ29: #N/A | BA29: #N/A | BB29: #N/A | BC29: #N/A | BD29: #N/A | BE29: #N/A | BF29: #N/A | BG29: #N/A | BH29: #N/A | BI29: #N/A | BJ29: #N/A | BK29: #N/A | BL29: #N/A | BM29: #N/A | BN29: #N/A | BO29: #N/A | BP29: #N/A | BQ29: #N/A | BR29: #N/A | BS29: #N/A | BT29: #N/A | BU29: #N/A | BV29: #N/A | BW29: #N/A | BX29: #N/A | BY29: #N/A | BZ29: #N/A | CA29: #N/A | CB29: #N/A | CC29: #N/A | CD29: #N/A | CE29: #N/A | CF29: #N/A | CG29: #N/A | CH29: #N/A | CI29: #N/A | CJ29: #N/A | CK29: #N/A | CL29: #N/A | CM29: #N/A | CN29: #N/A | CO29: #N/A | CP29: #N/A | CQ29: #N/A | CR29: #N/A | CS29: #N/A | CT29: #N/A | CU29: #N/A | CV29: #N/A | CW29: #N/A | CX29: #N/A | CY29: #N/A | CZ29: #N/A | DA29: #N/A | DB29: #N/A | DC29: #N/A | DD29: #N/A | DE29: #N/A | DF29: #N/A | DG29: #N/A | DH29: #N/A | DI29: #N/A | DJ29: #N/A | DK29: #N/A | DL29: #N/A | DM29: #N/A | DN29: #N/A | DO29: #N/A | DP29: #N/A | DQ29: #N/A | DR29: #N/A | DS29: #N/A | DT29: #N/A | DU29: #N/A | DV29: #N/A | DW29: #N/A | DX29: #N/A | DY29: #N/A | DZ29: #N/A | EA29: #N/A | EB29: #N/A | EC29: #N/A
D30: SS_04 | AP30: #N/A | AQ30: #N/A | AR30: #N/A | AS30: #N/A | AT30: #N/A | AU30: #N/A | AV30: #N/A | AW30: #N/A | AX30: #N/A | AY30: #N/A | AZ30: #N/A | BA30: #N/A | BB30: #N/A | BC30: #N/A | BD30: #N/A | BE30: #N/A | BF30: #N/A | BG30: #N/A | BH30: #N/A | BI30: #N/A | BJ30: #N/A | BK30: #N/A | BL30: #N/A | BM30: #N/A | BN30: #N/A | BO30: #N/A | BP30: #N/A | BQ30: #N/A | BR30: #N/A | BS30: #N/A | BT30: #N/A | BU30: #N/A | BV30: #N/A | BW30: #N/A | BX30: #N/A | BY30: #N/A | BZ30: #N/A | CA30: #N/A | CB30: #N/A | CC30: #N/A | CD30: #N/A | CE30: #N/A | CF30: #N/A | CG30: #N/A | CH30: #N/A | CI30: #N/A | CJ30: #N/A | CK30: #N/A | CL30: #N/A | CM30: #N/A | CN30: #N/A | CO30: #N/A | CP30: #N/A | CQ30: #N/A | CR30: #N/A | CS30: #N/A | CT30: #N/A | CU30: #N/A | CV30: #N/A | CW30: #N/A | CX30: #N/A | CY30: #N/A | CZ30: #N/A | DA30: #N/A | DB30: #N/A | DC30: #N/A | DD30: #N/A | DE30: #N/A | DF30: #N/A | DG30: #N/A | DH30: #N/A | DI30: #N/A | DJ30: #N/A | DK30: #N/A | DL30: #N/A | DM30: #N/A | DN30: #N/A | DO30: #N/A | DP30: #N/A | DQ30: #N/A | DR30: #N/A | DS30: #N/A | DT30: #N/A | DU30: #N/A | DV30: #N/A | DW30: #N/A | DX30: #N/A | DY30: #N/A | DZ30: #N/A | EA30: #N/A | EB30: #N/A | EC30: #N/A
D31: SS_05 | AP31: #N/A | AQ31: #N/A | AR31: #N/A | AS31: #N/A | AT31: #N/A | AU31: #N/A | AV31: #N/A | AW31: #N/A | AX31: #N/A | AY31: #N/A | AZ31: #N/A | BA31: #N/A | BB31: #N/A | BC31: #N/A | BD31: #N/A | BE31: #N/A | BF31: #N/A | BG31: #N/A | BH31: #N/A | BI31: #N/A | BJ31: #N/A | BK31: #N/A | BL31: #N/A | BM31: #N/A | BN31: #N/A | BO31: #N/A | BP31: #N/A | BQ31: #N/A | BR31: #N/A | BS31: #N/A | BT31: #N/A | BU31: #N/A | BV31: #N/A | BW31: #N/A | BX31: #N/A | BY31: #N/A | BZ31: #N/A | CA31: #N/A | CB31: #N/A | CC31: #N/A | CD31: #N/A | CE31: #N/A | CF31: #N/A | CG31: #N/A | CH31: #N/A | CI31: #N/A | CJ31: #N/A | CK31: #N/A | CL31: #N/A | CM31: #N/A | CN31: #N/A | CO31: #N/A | CP31: #N/A | CQ31: #N/A | CR31: #N/A | CS31: #N/A | CT31: #N/A | CU31: #N/A | CV31: #N/A | CW31: #N/A | CX31: #N/A | CY31: #N/A | CZ31: #N/A | DA31: #N/A | DB31: #N/A | DC31: #N/A | DD31: #N/A | DE31: #N/A | DF31: #N/A | DG31: #N/A | DH31: #N/A | DI31: #N/A | DJ31: #N/A | DK31: #N/A | DL31: #N/A | DM31: #N/A | DN31: #N/A | DO31: #N/A | DP31: #N/A | DQ31: #N/A | DR31: #N/A | DS31: #N/A | DT31: #N/A | DU31: #N/A | DV31: #N/A | DW31: #N/A | DX31: #N/A | DY31: #N/A | DZ31: #N/A | EA31: #N/A | EB31: #N/A | EC31: #N/A
D32: SS_07 | AP32: #N/A | AQ32: #N/A | AR32: #N/A | AS32: #N/A | AT32: #N/A | AU32: #N/A | AV32: #N/A | AW32: #N/A | AX32: #N/A | AY32: #N/A | AZ32: #N/A | BA32: #N/A | BB32: #N/A | BC32: #N/A | BD32: #N/A | BE32: #N/A | BF32: #N/A | BG32: #N/A | BH32: #N/A | BI32: #N/A | BJ32: #N/A | BK32: #N/A | BL32: #N/A | BM32: #N/A | BN32: #N/A | BO32: #N/A | BP32: #N/A | BQ32: #N/A | BR32: #N/A | BS32: #N/A | BT32: #N/A | BU32: #N/A | BV32: #N/A | BW32: #N/A | BX32: #N/A | BY32: #N/A | BZ32: #N/A | CA32: #N/A | CB32: #N/A | CC32: #N/A | CD32: #N/A | CE32: #N/A | CF32: #N/A | CG32: #N/A | CH32: #N/A | CI32: #N/A | CJ32: #N/A | CK32: #N/A | CL32: #N/A | CM32: #N/A | CN32: #N/A | CO32: #N/A | CP32: #N/A | CQ32: #N/A | CR32: #N/A | CS32: #N/A | CT32: #N/A | CU32: #N/A | CV32: #N/A | CW32: #N/A | CX32: #N/A | CY32: #N/A | CZ32: #N/A | DA32: #N/A | DB32: #N/A | DC32: #N/A | DD32: #N/A | DE32: #N/A | DF32: #N/A | DG32: #N/A | DH32: #N/A | DI32: #N/A | DJ32: #N/A | DK32: #N/A | DL32: #N/A | DM32: #N/A | DN32: #N/A | DO32: #N/A | DP32: #N/A | DQ32: #N/A | DR32: #N/A | DS32: #N/A | DT32: #N/A | DU32: #N/A | DV32: #N/A | DW32: #N/A | DX32: #N/A | DY32: #N/A | DZ32: #N/A | EA32: #N/A | EB32: #N/A | EC32: #N/A
D33: SS_08 | AP33: #N/A | AQ33: #N/A | AR33: #N/A | AS33: #N/A | AT33: #N/A | AU33: #N/A | AV33: #N/A | AW33: #N/A | AX33: #N/A | AY33: #N/A | AZ33: #N/A | BA33: #N/A | BB33: #N/A | BC33: #N/A | BD33: #N/A | BE33: #N/A | BF33: #N/A | BG33: #N/A | BH33: #N/A | BI33: #N/A | BJ33: #N/A | BK33: #N/A | BL33: #N/A | BM33: #N/A | BN33: #N/A | BO33: #N/A | BP33: #N/A | BQ33: #N/A | BR33: #N/A | BS33: #N/A | BT33: #N/A | BU33: #N/A | BV33: #N/A | BW33: #N/A | BX33: #N/A | BY33: #N/A | BZ33: #N/A | CA33: #N/A | CB33: #N/A | CC33: #N/A | CD33: #N/A | CE33: #N/A | CF33: #N/A | CG33: #N/A | CH33: #N/A | CI33: #N/A | CJ33: #N/A | CK33: #N/A | CL33: #N/A | CM33: #N/A | CN33: #N/A | CO33: #N/A | CP33: #N/A | CQ33: #N/A | CR33: #N/A | CS33: #N/A | CT33: #N/A | CU33: #N/A | CV33: #N/A | CW33: #N/A | CX33: #N/A | CY33: #N/A | CZ33: #N/A | DA33: #N/A | DB33: #N/A | DC33: #N/A | DD33: #N/A | DE33: #N/A | DF33: #N/A | DG33: #N/A | DH33: #N/A | DI33: #N/A | DJ33: #N/A | DK33: #N/A | DL33: #N/A | DM33: #N/A | DN33: #N/A | DO33: #N/A | DP33: #N/A | DQ33: #N/A | DR33: #N/A | DS33: #N/A | DT33: #N/A | DU33: #N/A | DV33: #N/A | DW33: #N/A | DX33: #N/A | DY33: #N/A | DZ33: #N/A | EA33: #N/A | EB33: #N/A | EC33: #N/A
D34: SS_09 | AP34: #N/A | AQ34: #N/A | AR34: #N/A | AS34: #N/A | AT34: #N/A | AU34: #N/A | AV34: #N/A | AW34: #N/A | AX34: #N/A | AY34: #N/A | AZ34: #N/A | BA34: #N/A | BB34: #N/A | BC34: #N/A | BD34: #N/A | BE34: #N/A | BF34: #N/A | BG34: #N/A | BH34: #N/A | BI34: #N/A | BJ34: #N/A | BK34: #N/A | BL34: #N/A | BM34: #N/A | BN34: #N/A | BO34: #N/A | BP34: #N/A | BQ34: #N/A | BR34: #N/A | BS34: #N/A | BT34: #N/A | BU34: #N/A | BV34: #N/A | BW34: #N/A | BX34: #N/A | BY34: #N/A | BZ34: #N/A | CA34: #N/A | CB34: #N/A | CC34: #N/A | CD34: #N/A | CE34: #N/A | CF34: #N/A | CG34: #N/A | CH34: #N/A | CI34: #N/A | CJ34: #N/A | CK34: #N/A | CL34: #N/A | CM34: #N/A | CN34: #N/A | CO34: #N/A | CP34: #N/A | CQ34: #N/A | CR34: #N/A | CS34: #N/A | CT34: #N/A | CU34: #N/A | CV34: #N/A | CW34: #N/A | CX34: #N/A | CY34: #N/A | CZ34: #N/A | DA34: #N/A | DB34: #N/A | DC34: #N/A | DD34: #N/A | DE34: #N/A | DF34: #N/A | DG34: #N/A | DH34: #N/A | DI34: #N/A | DJ34: #N/A | DK34: #N/A | DL34: #N/A | DM34: #N/A | DN34: #N/A | DO34: #N/A | DP34: #N/A | DQ34: #N/A | DR34: #N/A | DS34: #N/A | DT34: #N/A | DU34: #N/A | DV34: #N/A | DW34: #N/A | DX34: #N/A | DY34: #N/A | DZ34: #N/A | EA34: #N/A | EB34: #N/A | EC34: #N/A
D35: SS_10 | AP35: #N/A | AQ35: #N/A | AR35: #N/A | AS35: #N/A | AT35: #N/A | AU35: #N/A | AV35: #N/A | AW35: #N/A | AX35: #N/A | AY35: #N/A | AZ35: #N/A | BA35: #N/A | BB35: #N/A | BC35: #N/A | BD35: #N/A | BE35: #N/A | BF35: #N/A | BG35: #N/A | BH35: #N/A | BI35: #N/A | BJ35: #N/A | BK35: #N/A | BL35: #N/A | BM35: #N/A | BN35: #N/A | BO35: #N/A | BP35: #N/A | BQ35: #N/A | BR35: #N/A | BS35: #N/A | BT35: #N/A | BU35: #N/A | BV35: #N/A | BW35: #N/A | BX35: #N/A | BY35: #N/A | BZ35: #N/A | CA35: #N/A | CB35: #N/A | CC35: #N/A | CD35: #N/A | CE35: #N/A | CF35: #N/A | CG35: #N/A | CH35: #N/A | CI35: #N/A | CJ35: #N/A | CK35: #N/A | CL35: #N/A | CM35: #N/A | CN35: #N/A | CO35: #N/A | CP35: #N/A | CQ35: #N/A | CR35: #N/A | CS35: #N/A | CT35: #N/A | CU35: #N/A | CV35: #N/A | CW35: #N/A | CX35: #N/A | CY35: #N/A | CZ35: #N/A | DA35: #N/A | DB35: #N/A | DC35: #N/A | DD35: #N/A | DE35: #N/A | DF35: #N/A | DG35: #N/A | DH35: #N/A | DI35: #N/A | DJ35: #N/A | DK35: #N/A | DL35: #N/A | DM35: #N/A | DN35: #N/A | DO35: #N/A | DP35: #N/A | DQ35: #N/A | DR35: #N/A | DS35: #N/A | DT35: #N/A | DU35: #N/A | DV35: #N/A | DW35: #N/A | DX35: #N/A | DY35: #N/A | DZ35: #N/A | EA35: #N/A | EB35: #N/A | EC35: #N/A
D36: SS_11

Sheet Fleet_Det
D1: FLEET DETERMINATION | I1: Keterangan: | J1: Ganda | K1: Ditambah | L1: Dikeluarkan | Z1: * | EO1: * | EP1: *
A3: List_Front | D3: Sector | E3: Front No | F3: Hauler | G3: Dest | H3: Fleet Reff | I3: Truck1 | J3: Truck2 | K3: Truck3 | L3: Truck4 | M3: Truck5 | N3: Truck6 | O3: Truck7 | P3: Truck8 | Q3: Truck9 | R3: Truck10 | S3: Truck11 | T3: Truck12 | U3: Truck13 | V3: Truck14 | W3: Truck15 | BL3: DATA VALIDASI SAME FLEET
A4: {=IF((Front_Des[Sector]>0)*(Front_Des[Front No]>0),Front_Des[Sector]&"/"&TEXT(Front_Des[Front No],"00"),"")} -> BR1/01 | B4: {=_xlfn.UNIQUE(_xlfn._xlws.FILTER(Front_Des[Sector],Front_Des[Sector]>0))} -> BR1 | D4: BR1 | E4: 1 | F4: STM | G4: L18_S09 | I4: STM-A40_0121 | J4: STM-A40_0119 | K4: STM-A40_0107 | L4: STM-A40_0105 | M4: STM-A40_0136 | N4: STM-A40_0106 | O4: STM-A40_0098 | AA4: {=_xlfn.LET( _xlpm.tbl, Front_Des[], _xlpm.code, List_Front, _xlpm.same, Front_Des[Fleet Reff], _xlpm.truckCols, _xlfn.DROP(_xlpm.tbl,,_xlfn.XMATCH("Truck*",Front_Des[#Headers],2)-1), _xlpm.n, ROWS(_xlpm.tbl), _xlfn.BYROW( _xlfn.SEQUENCE(_xlpm.n), _xlfn.LAMBDA(_xlpm.i, _xlfn.LET( _xlpm.curFleet, IF(INDEX(_xlpm.same,_xlpm.i)="",INDEX(_xlpm.code,_xlpm.i),INDEX(_xlpm.same,_xlpm.i)), _xlpm.masterRow, IFERROR(_xlfn.XMATCH(_xlpm.curFleet,_xlpm.code,0),_xlpm.i), _xlpm.baseTrucks, _xlfn.UNIQUE(_xlfn.TOCOL(_xlfn.CHOOSEROWS(_xlpm.truckCols,_xlpm.masterRow),1)), _xlpm.curTrucks, _xlfn.UNIQUE(_xlfn.TOCOL(_xlfn.CHOOSEROWS(_xlpm.truckCols,_xlpm.i),1)), _xlpm.isMaster, _xlpm.i=_xlpm.masterRow, _xlpm.finalTrucks, IF(_xlpm.isMaster, _xlpm.baseTrucks, _xlfn.LET( _xlpm.remainBase, _xlfn._xlws.FILTER(_xlpm.baseTrucks,ISNA(_xlfn.XMATCH(_xlpm.baseTrucks,_xlpm.curTrucks,0)),""), _xlpm.newTrucks, _xlfn._xlws.FILTER(_xlpm.curTrucks,ISNA(_xlfn.XMATCH(_xlpm.curTrucks,_xlpm.baseTrucks,0)),""), _xlpm.combined, _xlfn.VSTACK(_xlpm.remainBase, _xlpm.newTrucks), _xlpm.list, IFERROR(_xlfn._xlws.FILTER(_xlpm.combined, _xlpm.combined>0),_xlpm.baseTrucks), _xlpm.list)), _xlpm.rslt, _xlfn.TEXTJOIN("|",,_xlfn._xlws.SORT(_xlfn.UNIQUE(_xlpm.finalTrucks))), IFERROR(_xlpm.rslt,"") ) ) ) )} -> STM-A40_0098|STM-A40_0105|STM-A40_0106|STM-A40_0107|STM-A40_0119|STM-A40_0121|STM-A40_0136 | AB4: {=_xlfn.LET( _xlpm.ore, _xlfn.XLOOKUP(Front_Des[Dest],Sample_Pending[Pile_ID],_xlfn.ANCHORARRAY(Regist!$AD$8),""), _xlpm.list, _xlfn.IFNA(_xlfn.DROP(_xlfn.REDUCE("", _xlpm.ore, _xlfn.LAMBDA(_xlpm.matriks,_xlpm.p, _xlfn.VSTACK(_xlpm.matriks, _xlfn.TOROW(IFERROR(_xlfn._xlws.SORT(_xlfn._xlws.FILTER(Sample_Pending[Pile_ID], (_xlfn.XLOOKUP(Sample_Pending[Pile_ID],Pile_area[pile_id],Pile_area[Ore]) = _xlpm.p)*(Sample_Pending[Status]="Cont"))), ""))))), 1),""), _xlfn.BYROW(_xlpm.list, _xlfn.LAMBDA(_xlpm.x, _xlfn.TEXTJOIN("|",, _xlfn._xlws.SORT(_xlfn.UNIQUE(_xlpm.x),,,TRUE)))))} -> BR-C6_S10|BR-C6_S10|BR-C6_S10|BR-C6_S10|L18_S09|L18_S09|L18_S09|L18_S09|S5_77|S5_77|S5_77|S5_88|S5_88|S5_88|S5_88|S5_93 | AC4: {=_xlfn.LET( _xlpm.p, HLG_01[[#This Row],[Front_ID]], _xlpm.baris_idx, MATCH(_xlpm.p, List_Front, 0), _xlpm.truk_valid, INDEX(_xlfn.ANCHORARRAY(Fleet_Det!$CE$4), _xlpm.baris_idx, ), _xlpm.fleet_str, INDEX(List_Unit_Fleet, _xlpm.baris_idx), _xlpm.daftar_truk, IFERROR(_xlfn.TEXTSPLIT(_xlpm.fleet_str, "|"), ""), _xlpm.daftar_truk_vec, _xlfn.TOCOL(_xlpm.daftar_truk, 1), _xlpm.hasil, _xlfn._xlws.FILTER(_xlpm.daftar_truk_vec, ISNUMBER(MATCH(_xlpm.daftar_truk_vec, _xlpm.truk_valid, 0)), ""), _xlfn.TOROW(_xlfn._xlws.SORT(_xlfn.UNIQUE(_xlpm.hasil))) )} | BL4: {=_xlfn.LET( _xlpm.tbl, Front_Des[], _xlpm.n_baris, ROWS(_xlpm.tbl), _xlpm.all_sec, Front_Des[Sector], _xlpm.all_hau, Front_Des[Hauler], _xlpm.all_codes, _xlpm.all_sec & "/" & TEXT(Front_Des[Front No], "00"), _xlfn.REDUCE( "Daftar Codes", _xlfn.SEQUENCE(_xlpm.n_baris), _xlfn.LAMBDA(_xlpm.matriks,_xlpm.i, _xlfn.LET( _xlpm.sec_ini, INDEX(_xlpm.all_sec, _xlpm.i), _xlpm.hau_ini, INDEX(_xlpm.all_hau, _xlpm.i), _xlpm.filter_cond, (_xlpm.all_sec <> "") * (_xlpm.all_sec = _xlpm.sec_ini) * (_xlpm.all_hau = _xlpm.hau_ini) * (_xlfn.SEQUENCE(_xlpm.n_baris) < _xlpm.i), _xlpm.hasil_filter, _xlfn._xlws.FILTER(_xlpm.all_codes, _xlpm.filter_cond, ""), _xlpm.hasil_bersih, IF( INDEX(_xlpm.hasil_filter, 1) = "", "", _xlfn.TOROW(_xlfn._xlws.SORT(_xlfn.UNIQUE(_xlpm.hasil_filter))) ), _xlfn.IFNA(IF(_xlpm.i = 1, _xlpm.hasil_bersih, _xlfn.VSTACK(_xlpm.matriks, _xlpm.hasil_bersih)),"") ) ) ) )} | CE4: {=_xlfn.DROP(_xlfn.REDUCE("", (Front_Des[Hauler]), _xlfn.LAMBDA(_xlpm.matriks,_xlpm.p, _xlfn.VSTACK(_xlpm.matriks, _xlfn.TOROW(IFERROR(_xlfn.DROP(_xlfn._xlws.SORT(_xlfn._xlws.FILTER(_xlfn.HSTACK(d_trucks[PT],d_trucks[No],_xlfn.ANCHORARRAY(Truck!$A$2)), (d_trucks[PT] = _xlpm.p)*(d_trucks[No]>0))),,2), ""))))), 1)} -> STM-A40_0019 | CF4: STM-A40_0022 | CG4: STM-A40_0067 | CH4: STM-A40_0068 | CI4: STM-A40_0069 | CJ4: STM-A40_0070 | CK4: STM-A40_0071 | CL4: STM-A40_0075 | CM4: STM-A40_0076 | CN4: STM-A40_0077 | CO4: STM-A40_0087 | CP4: STM-A40_0088 | CQ4: STM-A40_0089 | CR4: STM-A40_0093 | CS4: STM-A40_0095 | CT4: STM-A40_0096 | CU4: STM-A40_0097 | CV4: STM-A40_0098 | CW4: STM-A40_0099 | CX4: STM-A40_0100 | CY4: STM-A40_0101 | CZ4: STM-A40_0102 | DA4: STM-A40_0103 | DB4: STM-A40_0105 | DC4: STM-A40_0106 | DD4: STM-A40_0107 | DE4: STM-A40_0119 | DF4: STM-A40_0120 | DG4: STM-A40_0121 | DH4: STM-A40_0122 | DI4: STM-A40_0123 | DJ4: STM-A40_0125 | DK4: STM-A40_0131 | DL4: STM-A40_0132 | DM4: STM-A40_0133 | DN4: STM-A40_0135 | DO4: STM-A40_0136 | DP4: STM-A40_0141 | DQ4: STM-A40_0142 | DR4: STM-A40_0143 | DS4: STM-A40_0145 | DT4: STM-A40_0146 | DU4: STM-A40_2009 | DV4: STM-A40_2010 | DW4: STM-A40_2011 | DX4: STM-A40_2012 | DY4: STM-A40_2008
A5: BR1/02 | D5: BR1 | E5: 2 | F5: STM | G5: L18_S09 | I5: STM-A40_0087 | J5: STM-A40_0133 | K5: STM-A40_0132 | L5: STM-A40_0097 | M5: STM-A40_0068 | N5: STM-A40_0136 | O5: STM-A40_0069 | AA5: STM-A40_0068|STM-A40_0069|STM-A40_0087|STM-A40_0097|STM-A40_0132|STM-A40_0133|STM-A40_0136 | AB5: BR-C6_S10|BR-C6_S10|BR-C6_S10|BR-C6_S10|L18_S09|L18_S09|L18_S09|L18_S09|S5_77|S5_77|S5_77|S5_88|S5_88|S5_88|S5_88|S5_93 | BL5: BR1/01 | CE5: STM-A40_0019 | CF5: STM-A40_0022 | CG5: STM-A40_0067 | CH5: STM-A40_0068 | CI5: STM-A40_0069 | CJ5: STM-A40_0070 | CK5: STM-A40_0071 | CL5: STM-A40_0075 | CM5: STM-A40_0076 | CN5: STM-A40_0077 | CO5: STM-A40_0087 | CP5: STM-A40_0088 | CQ5: STM-A40_0089 | CR5: STM-A40_0093 | CS5: STM-A40_0095 | CT5: STM-A40_0096 | CU5: STM-A40_0097 | CV5: STM-A40_0098 | CW5: STM-A40_0099 | CX5: STM-A40_0100 | CY5: STM-A40_0101 | CZ5: STM-A40_0102 | DA5: STM-A40_0103 | DB5: STM-A40_0105 | DC5: STM-A40_0106 | DD5: STM-A40_0107 | DE5: STM-A40_0119 | DF5: STM-A40_0120 | DG5: STM-A40_0121 | DH5: STM-A40_0122 | DI5: STM-A40_0123 | DJ5: STM-A40_0125 | DK5: STM-A40_0131 | DL5: STM-A40_0132 | DM5: STM-A40_0133 | DN5: STM-A40_0135 | DO5: STM-A40_0136 | DP5: STM-A40_0141 | DQ5: STM-A40_0142 | DR5: STM-A40_0143 | DS5: STM-A40_0145 | DT5: STM-A40_0146 | DU5: STM-A40_2009 | DV5: STM-A40_2010 | DW5: STM-A40_2011 | DX5: STM-A40_2012 | DY5: STM-A40_2008
